Workbook

Sheet JANVIER 2015
A1: Algérienne des Eaux | G1: Centre de : BERROUAGHIA
A2: Zone d'Alger | G2: Agence de : BERROUAGHIA
A3: Unité de Médéa
A4: Suivi Pose Compteurs
A5: Mois de JANVIER 2015
A7: Date | B7: Nouveaux branchements | G7: Elimination du forfait | L7: Total (1+2)
B8: I | C8: II | D8: III | E8: IV | F8: Total (1) | G8: I | H8: II | I8: III | J8: IV | K8: Total (2)
A9: 1 | F9: =SUM(B9:E9) -> 0 | K9: =SUM(G9:J9) -> 0 | L9: =SUM(F9+K9) -> 0
A10: 2 | F10: =SUM(B10:E10) -> 0 | K10: =SUM(G10:J10) -> 0 | L10: =SUM(F10+K10) -> 0
A11: 3 | F11: =SUM(B11:E11) -> 0 | K11: =SUM(G11:J11) -> 0 | L11: =SUM(F11+K11) -> 0
A12: 4 | B12: 1 | F12: =SUM(B12:E12) -> 1 | G12: 11 | K12: =SUM(G12:J12) -> 11 | L12: =SUM(F12+K12) -> 12
A13: 5 | F13: =SUM(B13:E13) -> 0 | G13: 6 | K13: =SUM(G13:J13) -> 6 | L13: =SUM(F13+K13) -> 6
A14: 6 | F14: =SUM(B14:E14) -> 0 | G14: 9 | K14: =SUM(G14:J14) -> 9 | L14: =SUM(F14+K14) -> 9
A15: 7 | F15: =SUM(B15:E15) -> 0 | G15: 5 | K15: =SUM(G15:J15) -> 5 | L15: =SUM(F15+K15) -> 5
A16: 8 | B16: 1 | F16: =SUM(B16:E16) -> 1 | G16: 3 | H16: 1 | K16: =SUM(G16:J16) -> 4 | L16: =SUM(F16+K16) -> 5
A17: 9 | F17: =SUM(B17:E17) -> 0 | K17: =SUM(G17:J17) -> 0 | L17: =SUM(F17+K17) -> 0
A18: 10 | F18: =SUM(B18:E18) -> 0 | K18: =SUM(G18:J18) -> 0 | L18: =SUM(F18+K18) -> 0
A19: 11 | B19: 1 | F19: =SUM(B19:E19) -> 1 | K19: =SUM(G19:J19) -> 0 | L19: =SUM(F19+K19) -> 1
A20: 12 | F20: =SUM(B20:E20) -> 0 | H20: 1 | K20: =SUM(G20:J20) -> 1 | L20: =SUM(F20+K20) -> 1
A21: 13 | F21: =SUM(B21:E21) -> 0 | K21: =SUM(G21:J21) -> 0 | L21: =SUM(F21+K21) -> 0
A22: 14 | F22: =SUM(B22:E22) -> 0 | K22: =SUM(G22:J22) -> 0 | L22: =SUM(F22+K22) -> 0
A23: 15 | F23: =SUM(B23:E23) -> 0 | K23: =SUM(G23:J23) -> 0 | L23: =SUM(F23+K23) -> 0
A24: 16 | B24: 10 | F24: =SUM(B24:E24) -> 10 | K24: =SUM(G24:J24) -> 0 | L24: =SUM(F24+K24) -> 10
A25: 17 | B25: 17 | F25: =SUM(B25:E25) -> 17 | K25: =SUM(G25:J25) -> 0 | L25: =SUM(F25+K25) -> 17
A26: 18 | B26: 1 | F26: =SUM(B26:E26) -> 1 | G26: 1 | K26: =SUM(G26:J26) -> 1 | L26: =SUM(F26+K26) -> 2
A27: 19 | B27: 1 | F27: =SUM(B27:E27) -> 1 | K27: =SUM(G27:J27) -> 0 | L27: =SUM(F27+K27) -> 1
A28: 20 | B28: 1 | F28: =SUM(B28:E28) -> 1 | K28: =SUM(G28:J28) -> 0 | L28: =SUM(F28+K28) -> 1
A29: 21 | F29: =SUM(B29:E29) -> 0 | K29: =SUM(G29:J29) -> 0 | L29: =SUM(F29+K29) -> 0
A30: 22 | F30: =SUM(B30:E30) -> 0 | K30: =SUM(G30:J30) -> 0 | L30: =SUM(F30+K30) -> 0
A31: 23 | F31: =SUM(B31:E31) -> 0 | K31: =SUM(G31:J31) -> 0 | L31: =SUM(F31+K31) -> 0
A32: 24 | F32: =SUM(B32:E32) -> 0 | K32: =SUM(G32:J32) -> 0 | L32: =SUM(F32+K32) -> 0
A33: 25 | F33: =SUM(B33:E33) -> 0 | G33: 1 | K33: =SUM(G33:J33) -> 1 | L33: =SUM(F33+K33) -> 1
A34: 26 | F34: =SUM(B34:E34) -> 0 | K34: =SUM(G34:J34) -> 0 | L34: =SUM(F34+K34) -> 0
A35: 27 | F35: =SUM(B35:E35) -> 0 | K35: =SUM(G35:J35) -> 0 | L35: =SUM(F35+K35) -> 0
A36: 28 | B36: 1 | F36: =SUM(B36:E36) -> 1 | K36: =SUM(G36:J36) -> 0 | L36: =SUM(F36+K36) -> 1
A37: 29 | F37: =SUM(B37:E37) -> 0 | K37: =SUM(G37:J37) -> 0 | L37: =SUM(F37+K37) -> 0
A38: 30 | F38: =SUM(B38:E38) -> 0 | K38: =SUM(G38:J38) -> 0 | L38: =SUM(F38+K38) -> 0
A39: 31 | F39: =SUM(B39:E39) -> 0 | K39: =SUM(G39:J39) -> 0 | L39: =SUM(F39+K39) -> 0
B40: =SUM(B9:B39) -> 34 | C40: =SUM(C9:C39) -> 0 | D40: =SUM(D9:D39) -> 0 | E40: =SUM(E9:E39) -> 0 | F40: =SUM(F9:F39) -> 34 | G40: =SUM(G9:G39) -> 36 | H40: =SUM(H9:H39) -> 2 | I40: =SUM(I9:I39) -> 0 | ... L40: =SUM(L9:L39) -> 72
G42: Neufs | I42: Rénovés
...

Sheet FEVRIER 2015
A1: Algérienne des Eaux | G1: Centre de : BERROUAGHIA
A2: Zone d'Alger | G2: Agence de : BERROUAGHIA
A3: Unité de Médéa
A4: Suivi Pose Compteurs
A5: Mois de FEVRIER 2015
A6: Date | B6: Nouveaux branchements | G6: Elimination du forfait | L6: Total (1+2)
B7: I | C7: II | D7: III | E7: IV | F7: Total (1) | G7: I | H7: II | I7: III | J7: IV | K7: Total (2)
A8: 1 | F8: =SUM(B8:E8) -> 0 | K8: =SUM(G8:J8) -> 0 | L8: =SUM(F8+K8) -> 0
A9: 2 | D9: 2 | F9: =SUM(B9:E9) -> 2 | G9: 1 | K9: =SUM(G9:J9) -> 1 | L9: =SUM(F9+K9) -> 3
A10: 3 | F10: =SUM(B10:E10) -> 0 | K10: =SUM(G10:J10) -> 0 | L10: =SUM(F10+K10) -> 0
A11: 4 | F11: =SUM(B11:E11) -> 0 | K11: =SUM(G11:J11) -> 0 | L11: =SUM(F11+K11) -> 0
A12: 5 | F12: =SUM(B12:E12) -> 0 | G12: 1 | K12: =SUM(G12:J12) -> 1 | L12: =SUM(F12+K12) -> 1
A13: 6 | F13: =SUM(B13:E13) -> 0 | K13: =SUM(G13:J13) -> 0 | L13: =SUM(F13+K13) -> 0
A14: 7 | F14: =SUM(B14:E14) -> 0 | K14: =SUM(G14:J14) -> 0 | L14: =SUM(F14+K14) -> 0
A15: 8 | F15: =SUM(B15:E15) -> 0 | K15: =SUM(G15:J15) -> 0 | L15: =SUM(F15+K15) -> 0
A16: 9 | F16: =SUM(B16:E16) -> 0 | K16: =SUM(G16:J16) -> 0 | L16: =SUM(F16+K16) -> 0
A17: 10 | F17: =SUM(B17:E17) -> 0 | K17: =SUM(G17:J17) -> 0 | L17: =SUM(F17+K17) -> 0
A18: 11 | F18: =SUM(B18:E18) -> 0 | K18: =SUM(G18:J18) -> 0 | L18: =SUM(F18+K18) -> 0
A19: 12 | F19: =SUM(B19:E19) -> 0 | G19: 13 | K19: =SUM(G19:J19) -> 13 | L19: =SUM(F19+K19) -> 13
A20: 13 | F20: =SUM(B20:E20) -> 0 | K20: =SUM(G20:J20) -> 0 | L20: =SUM(F20+K20) -> 0
A21: 14 | F21: =SUM(B21:E21) -> 0 | K21: =SUM(G21:J21) -> 0 | L21: =SUM(F21+K21) -> 0
A22: 15 | B22: 2 | F22: =SUM(B22:E22) -> 2 | K22: =SUM(G22:J22) -> 0 | L22: =SUM(F22+K22) -> 2
A23: 16 | F23: =SUM(B23:E23) -> 0 | K23: =SUM(G23:J23) -> 0 | L23: =SUM(F23+K23) -> 0
A24: 17 | B24: 1 | F24: =SUM(B24:E24) -> 1 | K24: =SUM(G24:J24) -> 0 | L24: =SUM(F24+K24) -> 1
A25: 18 | F25: =SUM(B25:E25) -> 0 | K25: =SUM(G25:J25) -> 0 | L25: =SUM(F25+K25) -> 0
A26: 19 | F26: =SUM(B26:E26) -> 0 | K26: =SUM(G26:J26) -> 0 | L26: =SUM(F26+K26) -> 0
A27: 20 | F27: =SUM(B27:E27) -> 0 | K27: =SUM(G27:J27) -> 0 | L27: =SUM(F27+K27) -> 0
A28: 21 | F28: =SUM(B28:E28) -> 0 | K28: =SUM(G28:J28) -> 0 | L28: =SUM(F28+K28) -> 0
A29: 22 | F29: =SUM(B29:E29) -> 0 | K29: =SUM(G29:J29) -> 0 | L29: =SUM(F29+K29) -> 0
A30: 23 | F30: =SUM(B30:E30) -> 0 | K30: =SUM(G30:J30) -> 0 | L30: =SUM(F30+K30) -> 0
A31: 24 | B31: 1 | F31: =SUM(B31:E31) -> 1 | K31: =SUM(G31:J31) -> 0 | L31: =SUM(F31+K31) -> 1
A32: 25 | F32: =SUM(B32:E32) -> 0 | K32: =SUM(G32:J32) -> 0 | L32: =SUM(F32+K32) -> 0
A33: 26 | F33: =SUM(B33:E33) -> 0 | G33: 3 | K33: =SUM(G33:J33) -> 3 | L33: =SUM(F33+K33) -> 3
A34: 27 | F34: =SUM(B34:E34) -> 0 | K34: =SUM(G34:J34) -> 0 | L34: =SUM(F34+K34) -> 0
A35: 28 | F35: =SUM(B35:E35) -> 0 | K35: =SUM(G35:J35) -> 0 | L35: =SUM(F35+K35) -> 0
A36: 29 | F36: =SUM(B36:E36) -> 0 | K36: =SUM(G36:J36) -> 0 | L36: =SUM(F36+K36) -> 0
A37: 30 | F37: =SUM(B37:E37) -> 0 | K37: =SUM(G37:J37) -> 0 | L37: =SUM(F37+K37) -> 0
A38: 31 | F38: =SUM(B38:E38) -> 0 | K38: =SUM(G38:J38) -> 0 | L38: =SUM(F38+K38) -> 0
B39: =SUM(B8:B38) -> 4 | C39: =SUM(C8:C38) -> 0 | D39: =SUM(D8:D38) -> 2 | E39: =SUM(E8:E38) -> 0 | F39: =SUM(F8:F38) -> 6 | G39: =SUM(G8:G38) -> 18 | H39: =SUM(H8:H38) -> 0 | I39: =SUM(I8:I38) -> 0 | ... L39: =SUM(L8:L38) -> 24
G41: Neufs | I41: Rénovés
...

Sheet Mars 2015
A1: Algérienne des Eaux | G1: Centre de : BERROUAGHIA
A2: Zone d'Alger | G2: Agence de : BERROUAGHIA
A3: Unité de Médéa
A5: Suivi Pose Compteurs
A6: Mois de Mars 2015
A8: Date | B8: Nouveaux branchements | G8: Elimination du forfait | L8: Total (1+2)
B9: I | C9: II | D9: III | E9: IV | F9: Total (1) | G9: I | H9: II | I9: III | J9: IV | K9: Total (2)
A10: 1 | F10: =SUM(B10:E10) -> 0 | G10: 1 | K10: =SUM(G10:J10) -> 1 | L10: =SUM(F10+K10) -> 1
A11: 2 | B11: 2 | F11: =SUM(B11:E11) -> 2 | K11: =SUM(G11:J11) -> 0 | L11: =SUM(F11+K11) -> 2
A12: 3 | F12: =SUM(B12:E12) -> 0 | G12: 1 | I12: 1 | K12: =SUM(G12:J12) -> 2 | L12: =SUM(F12+K12) -> 2
A13: 4 | D13: 1 | F13: =SUM(B13:E13) -> 1 | K13: =SUM(G13:J13) -> 0 | L13: =SUM(F13+K13) -> 1
A14: 5 | F14: =SUM(B14:E14) -> 0 | G14: 1 | K14: =SUM(G14:J14) -> 1 | L14: =SUM(F14+K14) -> 1
A15: 6 | F15: =SUM(B15:E15) -> 0 | K15: =SUM(G15:J15) -> 0 | L15: =SUM(F15+K15) -> 0
A16: 7 | F16: =SUM(B16:E16) -> 0 | K16: =SUM(G16:J16) -> 0 | L16: =SUM(F16+K16) -> 0
A17: 8 | F17: =SUM(B17:E17) -> 0 | K17: =SUM(G17:J17) -> 0 | L17: =SUM(F17+K17) -> 0
A18: 9 | F18: =SUM(B18:E18) -> 0 | K18: =SUM(G18:J18) -> 0 | L18: =SUM(F18+K18) -> 0
A19: 10 | F19: =SUM(B19:E19) -> 0 | K19: =SUM(G19:J19) -> 0 | L19: =SUM(F19+K19) -> 0
A20: 11 | F20: =SUM(B20:E20) -> 0 | G20: 1 | K20: =SUM(G20:J20) -> 1 | L20: =SUM(F20+K20) -> 1
A21: 12 | B21: 1 | F21: =SUM(B21:E21) -> 1 | G21: 2 | K21: =SUM(G21:J21) -> 2 | L21: =SUM(F21+K21) -> 3
A22: 13 | F22: =SUM(B22:E22) -> 0 | K22: =SUM(G22:J22) -> 0 | L22: =SUM(F22+K22) -> 0
A23: 14 | B23: 10 | F23: =SUM(B23:E23) -> 10 | K23: =SUM(G23:J23) -> 0 | L23: =SUM(F23+K23) -> 10
A24: 15 | F24: =SUM(B24:E24) -> 0 | K24: =SUM(G24:J24) -> 0 | L24: =SUM(F24+K24) -> 0
A25: 16 | F25: =SUM(B25:E25) -> 0 | G25: 1 | K25: =SUM(G25:J25) -> 1 | L25: =SUM(F25+K25) -> 1
A26: 17 | F26: =SUM(B26:E26) -> 0 | K26: =SUM(G26:J26) -> 0 | L26: =SUM(F26+K26) -> 0
A27: 18 | F27: =SUM(B27:E27) -> 0 | K27: =SUM(G27:J27) -> 0 | L27: =SUM(F27+K27) -> 0
A28: 19 | D28: 1 | F28: =SUM(B28:E28) -> 1 | K28: =SUM(G28:J28) -> 0 | L28: =SUM(F28+K28) -> 1
A29: 20 | F29: =SUM(B29:E29) -> 0 | K29: =SUM(G29:J29) -> 0 | L29: =SUM(F29+K29) -> 0
A30: 21 | F30: =SUM(B30:E30) -> 0 | K30: =SUM(G30:J30) -> 0 | L30: =SUM(F30+K30) -> 0
A31: 22 | D31: 1 | F31: =SUM(B31:E31) -> 1 | K31: =SUM(G31:J31) -> 0 | L31: =SUM(F31+K31) -> 1
A32: 23 | F32: =SUM(B32:E32) -> 0 | K32: =SUM(G32:J32) -> 0 | L32: =SUM(F32+K32) -> 0
A33: 24 | F33: =SUM(B33:E33) -> 0 | K33: =SUM(G33:J33) -> 0 | L33: =SUM(F33+K33) -> 0
A34: 25 | B34: 3 | F34: =SUM(B34:E34) -> 3 | K34: =SUM(G34:J34) -> 0 | L34: =SUM(F34+K34) -> 3
A35: 26 | F35: =SUM(B35:E35) -> 0 | K35: =SUM(G35:J35) -> 0 | L35: =SUM(F35+K35) -> 0
A36: 27 | F36: =SUM(B36:E36) -> 0 | K36: =SUM(G36:J36) -> 0 | L36: =SUM(F36+K36) -> 0
A37: 28 | F37: =SUM(B37:E37) -> 0 | K37: =SUM(G37:J37) -> 0 | L37: =SUM(F37+K37) -> 0
A38: 29 | B38: 11 | F38: =SUM(B38:E38) -> 11 | G38: 2 | K38: =SUM(G38:J38) -> 2 | L38: =SUM(F38+K38) -> 13
A39: 30 | F39: =SUM(B39:E39) -> 0 | K39: =SUM(G39:J39) -> 0 | L39: =SUM(F39+K39) -> 0
A40: 31 | F40: =SUM(B40:E40) -> 0 | K40: =SUM(G40:J40) -> 0 | L40: =SUM(F40+K40) -> 0
B41: =SUM(B10:B40) -> 27 | C41: =SUM(C10:C40) -> 0 | D41: =SUM(D10:D40) -> 3 | E41: =SUM(E10:E40) -> 0 | F41: =SUM(F10:F40) -> 30 | G41: =SUM(G10:G40) -> 9 | H41: =SUM(H10:H40) -> 0 | I41: =SUM(I10:I40) -> 1 | ... L41: =SUM(L10:L40) -> 40
G43: Neufs | I43: Rénovés
...

Sheet Avril 2015
A1: Algérienne des Eaux | G1: Centre de : BERROUAGHIA
A2: Zone d'Alger | G2: Agence de : BERROUAGHIA
A3: Unité de Médéa
A5: Suivi Pose Compteurs
A6: Mois de Avril 2015
A8: Date | B8: Nouveaux branchements | G8: Elimination du forfait | L8: Total (1+2)
B9: I | C9: II | D9: III | E9: IV | F9: Total (1) | G9: I | H9: II | I9: III | J9: IV | K9: Total (2)
A10: 1 | B10: 3 | F10: =SUM(B10:E10) -> 3 | G10: 2 | K10: =SUM(G10:J10) -> 2 | L10: =SUM(F10+K10) -> 5
A11: 2 | B11: 1 | F11: =SUM(B11:E11) -> 1 | G11: 1 | K11: =SUM(G11:J11) -> 1 | L11: =SUM(F11+K11) -> 2
A12: 3 | F12: =SUM(B12:E12) -> 0 | K12: =SUM(G12:J12) -> 0 | L12: =SUM(F12+K12) -> 0
A13: 4 | F13: =SUM(B13:E13) -> 0 | K13: =SUM(G13:J13) -> 0 | L13: =SUM(F13+K13) -> 0
A14: 5 | F14: =SUM(B14:E14) -> 0 | K14: =SUM(G14:J14) -> 0 | L14: =SUM(F14+K14) -> 0
A15: 6 | F15: =SUM(B15:E15) -> 0 | K15: =SUM(G15:J15) -> 0 | L15: =SUM(F15+K15) -> 0
A16: 7 | F16: =SUM(B16:E16) -> 0 | G16: 2 | K16: =SUM(G16:J16) -> 2 | L16: =SUM(F16+K16) -> 2
A17: 8 | F17: =SUM(B17:E17) -> 0 | K17: =SUM(G17:J17) -> 0 | L17: =SUM(F17+K17) -> 0
A18: 9 | D18: 1 | F18: =SUM(B18:E18) -> 1 | G18: 3 | K18: =SUM(G18:J18) -> 3 | L18: =SUM(F18+K18) -> 4
A19: 10 | F19: =SUM(B19:E19) -> 0 | K19: =SUM(G19:J19) -> 0 | L19: =SUM(F19+K19) -> 0
A20: 11 | B20: 2 | F20: =SUM(B20:E20) -> 2 | K20: =SUM(G20:J20) -> 0 | L20: =SUM(F20+K20) -> 2
A21: 12 | F21: =SUM(B21:E21) -> 0 | K21: =SUM(G21:J21) -> 0 | L21: =SUM(F21+K21) -> 0
A22: 13 | F22: =SUM(B22:E22) -> 0 | K22: =SUM(G22:J22) -> 0 | L22: =SUM(F22+K22) -> 0
A23: 14 | B23: 8 | F23: =SUM(B23:E23) -> 8 | G23: 2 | K23: =SUM(G23:J23) -> 2 | L23: =SUM(F23+K23) -> 10
A24: 15 | B24: 1 | D24: 1 | F24: =SUM(B24:E24) -> 2 | K24: =SUM(G24:J24) -> 0 | L24: =SUM(F24+K24) -> 2
A25: 16 | C25: 1 | F25: =SUM(B25:E25) -> 1 | K25: =SUM(G25:J25) -> 0 | L25: =SUM(F25+K25) -> 1
A26: 17 | F26: =SUM(B26:E26) -> 0 | K26: =SUM(G26:J26) -> 0 | L26: =SUM(F26+K26) -> 0
A27: 18 | F27: =SUM(B27:E27) -> 0 | K27: =SUM(G27:J27) -> 0 | L27: =SUM(F27+K27) -> 0
A28: 19 | B28: 1 | F28: =SUM(B28:E28) -> 1 | K28: =SUM(G28:J28) -> 0 | L28: =SUM(F28+K28) -> 1
A29: 20 | B29: 1 | F29: =SUM(B29:E29) -> 1 | K29: =SUM(G29:J29) -> 0 | L29: =SUM(F29+K29) -> 1
A30: 21 | B30: 1 | F30: =SUM(B30:E30) -> 1 | G30: 1 | K30: =SUM(G30:J30) -> 1 | L30: =SUM(F30+K30) -> 2
A31: 22 | B31: 1 | E31: 1 | F31: =SUM(B31:E31) -> 2 | G31: 3 | K31: =SUM(G31:J31) -> 3 | L31: =SUM(F31+K31) -> 5
A32: 23 | F32: =SUM(B32:E32) -> 0 | G32: 15 | I32: 1 | K32: =SUM(G32:J32) -> 16 | L32: =SUM(F32+K32) -> 16
A33: 24 | F33: =SUM(B33:E33) -> 0 | K33: =SUM(G33:J33) -> 0 | L33: =SUM(F33+K33) -> 0
A34: 25 | F34: =SUM(B34:E34) -> 0 | G34: 9 | K34: =SUM(G34:J34) -> 9 | L34: =SUM(F34+K34) -> 9
A35: 26 | B35: 1 | F35: =SUM(B35:E35) -> 1 | I35: 1 | K35: =SUM(G35:J35) -> 1 | L35: =SUM(F35+K35) -> 2
A36: 27 | F36: =SUM(B36:E36) -> 0 | K36: =SUM(G36:J36) -> 0 | L36: =SUM(F36+K36) -> 0
A37: 28 | C37: 2 | D37: 1 | F37: =SUM(B37:E37) -> 3 | K37: =SUM(G37:J37) -> 0 | L37: =SUM(F37+K37) -> 3
A38: 29 | F38: =SUM(B38:E38) -> 0 | K38: =SUM(G38:J38) -> 0 | L38: =SUM(F38+K38) -> 0
A39: 30 | F39: =SUM(B39:E39) -> 0 | K39: =SUM(G39:J39) -> 0 | L39: =SUM(F39+K39) -> 0
A40: 31 | F40: =SUM(B40:E40) -> 0 | K40: =SUM(G40:J40) -> 0 | L40: =SUM(F40+K40) -> 0
B41: =SUM(B10:B40) -> 20 | C41: =SUM(C10:C40) -> 3 | D41: =SUM(D10:D40) -> 3 | E41: =SUM(E10:E40) -> 1 | F41: =SUM(F10:F40) -> 27 | G41: =SUM(G10:G40) -> 38 | H41: =SUM(H10:H40) -> 0 | I41: =SUM(I10:I40) -> 2 | ... L41: =SUM(L10:L40) -> 67
G43: Neufs | I43: Rénovés
...

Sheet Mai 2015
A1: Algérienne des Eaux | G1: Centre de : BERROUAGHIA
A2: Zone d'Alger | G2: Agence de : BERROUAGHIA
A3: Unité de Médéa
A5: Suivi Pose Compteurs
A6: Mois de Mai 2015
A8: Date | B8: Nouveaux branchements | G8: Elimination du forfait | L8: Total (1+2)
B9: I | C9: II | D9: III | E9: IV | F9: Total (1) | G9: I | H9: II | I9: III | J9: IV | K9: Total (2)
A10: 1 | F10: =SUM(B10:E10) -> 0 | K10: =SUM(G10:J10) -> 0 | L10: =SUM(F10+K10) -> 0
A11: 2 | F11: =SUM(B11:E11) -> 0 | K11: =SUM(G11:J11) -> 0 | L11: =SUM(F11+K11) -> 0
A12: 3 | B12: 4 | D12: 1 | F12: =SUM(B12:E12) -> 5 | K12: =SUM(G12:J12) -> 0 | L12: =SUM(F12+K12) -> 5
A13: 4 | D13: 1 | E13: 1 | F13: =SUM(B13:E13) -> 2 | K13: =SUM(G13:J13) -> 0 | L13: =SUM(F13+K13) -> 2
A14: 5 | B14: 1 | F14: =SUM(B14:E14) -> 1 | K14: =SUM(G14:J14) -> 0 | L14: =SUM(F14+K14) -> 1
A15: 6 | F15: =SUM(B15:E15) -> 0 | K15: =SUM(G15:J15) -> 0 | L15: =SUM(F15+K15) -> 0
A16: 7 | F16: =SUM(B16:E16) -> 0 | K16: =SUM(G16:J16) -> 0 | L16: =SUM(F16+K16) -> 0
A17: 8 | F17: =SUM(B17:E17) -> 0 | K17: =SUM(G17:J17) -> 0 | L17: =SUM(F17+K17) -> 0
A18: 9 | F18: =SUM(B18:E18) -> 0 | K18: =SUM(G18:J18) -> 0 | L18: =SUM(F18+K18) -> 0
A19: 10 | F19: =SUM(B19:E19) -> 0 | K19: =SUM(G19:J19) -> 0 | L19: =SUM(F19+K19) -> 0
A20: 11 | F20: =SUM(B20:E20) -> 0 | K20: =SUM(G20:J20) -> 0 | L20: =SUM(F20+K20) -> 0
A21: 12 | F21: =SUM(B21:E21) -> 0 | K21: =SUM(G21:J21) -> 0 | L21: =SUM(F21+K21) -> 0
A22: 13 | F22: =SUM(B22:E22) -> 0 | G22: 2 | K22: =SUM(G22:J22) -> 2 | L22: =SUM(F22+K22) -> 2
A23: 14 | F23: =SUM(B23:E23) -> 0 | G23: 1 | K23: =SUM(G23:J23) -> 1 | L23: =SUM(F23+K23) -> 1
A24: 15 | F24: =SUM(B24:E24) -> 0 | K24: =SUM(G24:J24) -> 0 | L24: =SUM(F24+K24) -> 0
A25: 16 | F25: =SUM(B25:E25) -> 0 | K25: =SUM(G25:J25) -> 0 | L25: =SUM(F25+K25) -> 0
A26: 17 | B26: 2 | E26: 1 | F26: =SUM(B26:E26) -> 3 | K26: =SUM(G26:J26) -> 0 | L26: =SUM(F26+K26) -> 3
A27: 18 | C27: 1 | F27: =SUM(B27:E27) -> 1 | K27: =SUM(G27:J27) -> 0 | L27: =SUM(F27+K27) -> 1
A28: 19 | F28: =SUM(B28:E28) -> 0 | K28: =SUM(G28:J28) -> 0 | L28: =SUM(F28+K28) -> 0
A29: 20 | F29: =SUM(B29:E29) -> 0 | K29: =SUM(G29:J29) -> 0 | L29: =SUM(F29+K29) -> 0
A30: 21 | B30: 1 | F30: =SUM(B30:E30) -> 1 | K30: =SUM(G30:J30) -> 0 | L30: =SUM(F30+K30) -> 1
A31: 22 | F31: =SUM(B31:E31) -> 0 | K31: =SUM(G31:J31) -> 0 | L31: =SUM(F31+K31) -> 0
A32: 23 | F32: =SUM(B32:E32) -> 0 | K32: =SUM(G32:J32) -> 0 | L32: =SUM(F32+K32) -> 0
A33: 24 | F33: =SUM(B33:E33) -> 0 | K33: =SUM(G33:J33) -> 0 | L33: =SUM(F33+K33) -> 0
A34: 25 | D34: 3 | F34: =SUM(B34:E34) -> 3 | G34: 2 | K34: =SUM(G34:J34) -> 2 | L34: =SUM(F34+K34) -> 5
A35: 26 | F35: =SUM(B35:E35) -> 0 | K35: =SUM(G35:J35) -> 0 | L35: =SUM(F35+K35) -> 0
A36: 27 | B36: 3 | F36: =SUM(B36:E36) -> 3 | K36: =SUM(G36:J36) -> 0 | L36: =SUM(F36+K36) -> 3
A37: 28 | F37: =SUM(B37:E37) -> 0 | K37: =SUM(G37:J37) -> 0 | L37: =SUM(F37+K37) -> 0
A38: 29 | F38: =SUM(B38:E38) -> 0 | G38: 1 | K38: =SUM(G38:J38) -> 1 | L38: =SUM(F38+K38) -> 1
A39: 30 | F39: =SUM(B39:E39) -> 0 | K39: =SUM(G39:J39) -> 0 | L39: =SUM(F39+K39) -> 0
A40: 31 | B40: 2 | F40: =SUM(B40:E40) -> 2 | K40: =SUM(G40:J40) -> 0 | L40: =SUM(F40+K40) -> 2
B41: =SUM(B10:B40) -> 13 | C41: =SUM(C10:C40) -> 1 | D41: =SUM(D10:D40) -> 5 | E41: =SUM(E10:E40) -> 2 | F41: =SUM(F10:F40) -> 21 | G41: =SUM(G10:G40) -> 6 | H41: =SUM(H10:H40) -> 0 | I41: =SUM(I10:I40) -> 0 | ... L41: =SUM(L10:L40) -> 27
G43: Neufs | I43: Rénovés
...

Sheet Juin 2015
A1: Algérienne des Eaux | G1: Centre de : BERROUAGHIA
A2: Zone d'Alger | G2: Agence de : BERROUAGHIA
A3: Unité de Médéa
A5: Suivi Pose Compteurs
A6: Mois de Juin 2015
A8: Date | B8: Nouveaux branchements | G8: Elimination du forfait | L8: Total (1+2)
B9: I | C9: II | D9: III | E9: IV | F9: Total (1) | G9: I | H9: II | I9: III | J9: IV | K9: Total (2)
A10: 1 | F10: =SUM(B10:E10) -> 0 | K10: =SUM(G10:J10) -> 0 | L10: =SUM(F10+K10) -> 0
A11: 2 | B11: 18 | F11: =SUM(B11:E11) -> 18 | G11: 1 | K11: =SUM(G11:J11) -> 1 | L11: =SUM(F11+K11) -> 19
A12: 3 | B12: 5 | F12: =SUM(B12:E12) -> 5 | K12: =SUM(G12:J12) -> 0 | L12: =SUM(F12+K12) -> 5
A13: 4 | F13: =SUM(B13:E13) -> 0 | K13: =SUM(G13:J13) -> 0 | L13: =SUM(F13+K13) -> 0
A14: 5 | F14: =SUM(B14:E14) -> 0 | K14: =SUM(G14:J14) -> 0 | L14: =SUM(F14+K14) -> 0
A15: 6 | F15: =SUM(B15:E15) -> 0 | K15: =SUM(G15:J15) -> 0 | L15: =SUM(F15+K15) -> 0
A16: 7 | F16: =SUM(B16:E16) -> 0 | K16: =SUM(G16:J16) -> 0 | L16: =SUM(F16+K16) -> 0
A17: 8 | F17: =SUM(B17:E17) -> 0 | K17: =SUM(G17:J17) -> 0 | L17: =SUM(F17+K17) -> 0
A18: 9 | B18: 3 | F18: =SUM(B18:E18) -> 3 | K18: =SUM(G18:J18) -> 0 | L18: =SUM(F18+K18) -> 3
A19: 10 | F19: =SUM(B19:E19) -> 0 | K19: =SUM(G19:J19) -> 0 | L19: =SUM(F19+K19) -> 0
A20: 11 | F20: =SUM(B20:E20) -> 0 | G20: 2 | H20: 1 | K20: =SUM(G20:J20) -> 3 | L20: =SUM(F20+K20) -> 3
A21: 12 | F21: =SUM(B21:E21) -> 0 | K21: =SUM(G21:J21) -> 0 | L21: =SUM(F21+K21) -> 0
A22: 13 | F22: =SUM(B22:E22) -> 0 | K22: =SUM(G22:J22) -> 0 | L22: =SUM(F22+K22) -> 0
A23: 14 | F23: =SUM(B23:E23) -> 0 | K23: =SUM(G23:J23) -> 0 | L23: =SUM(F23+K23) -> 0
A24: 15 | F24: =SUM(B24:E24) -> 0 | G24: 1 | K24: =SUM(G24:J24) -> 1 | L24: =SUM(F24+K24) -> 1
A25: 16 | F25: =SUM(B25:E25) -> 0 | K25: =SUM(G25:J25) -> 0 | L25: =SUM(F25+K25) -> 0
A26: 17 | F26: =SUM(B26:E26) -> 0 | K26: =SUM(G26:J26) -> 0 | L26: =SUM(F26+K26) -> 0
A27: 18 | B27: 1 | F27: =SUM(B27:E27) -> 1 | G27: 9 | K27: =SUM(G27:J27) -> 9 | L27: =SUM(F27+K27) -> 10
A28: 19 | F28: =SUM(B28:E28) -> 0 | K28: =SUM(G28:J28) -> 0 | L28: =SUM(F28+K28) -> 0
A29: 20 | F29: =SUM(B29:E29) -> 0 | K29: =SUM(G29:J29) -> 0 | L29: =SUM(F29+K29) -> 0
A30: 21 | F30: =SUM(B30:E30) -> 0 | G30: 5 | K30: =SUM(G30:J30) -> 5 | L30: =SUM(F30+K30) -> 5
A31: 22 | B31: 2 | F31: =SUM(B31:E31) -> 2 | G31: 2 | K31: =SUM(G31:J31) -> 2 | L31: =SUM(F31+K31) -> 4
A32: 23 | B32: 1 | F32: =SUM(B32:E32) -> 1 | G32: 2 | K32: =SUM(G32:J32) -> 2 | L32: =SUM(F32+K32) -> 3
A33: 24 | B33: 2 | F33: =SUM(B33:E33) -> 2 | G33: 2 | K33: =SUM(G33:J33) -> 2 | L33: =SUM(F33+K33) -> 4
A34: 25 | B34: 2 | F34: =SUM(B34:E34) -> 2 | G34: 7 | K34: =SUM(G34:J34) -> 7 | L34: =SUM(F34+K34) -> 9
A35: 26 | F35: =SUM(B35:E35) -> 0 | K35: =SUM(G35:J35) -> 0 | L35: =SUM(F35+K35) -> 0
A36: 27 | F36: =SUM(B36:E36) -> 0 | G36: 10 | K36: =SUM(G36:J36) -> 10 | L36: =SUM(F36+K36) -> 10
A37: 28 | B37: 2 | F37: =SUM(B37:E37) -> 2 | G37: 10 | K37: =SUM(G37:J37) -> 10 | L37: =SUM(F37+K37) -> 12
A38: 29 | B38: 1 | F38: =SUM(B38:E38) -> 1 | G38: 9 | H38: 1 | K38: =SUM(G38:J38) -> 10 | L38: =SUM(F38+K38) -> 11
A39: 30 | D39: 1 | F39: =SUM(B39:E39) -> 1 | K39: =SUM(G39:J39) -> 0 | L39: =SUM(F39+K39) -> 1
A40: 31 | F40: =SUM(B40:E40) -> 0 | K40: =SUM(G40:J40) -> 0 | L40: =SUM(F40+K40) -> 0
B41: =SUM(B10:B40) -> 37 | C41: =SUM(C10:C40) -> 0 | D41: =SUM(D10:D40) -> 1 | E41: =SUM(E10:E40) -> 0 | F41: =SUM(F10:F40) -> 38 | G41: =SUM(G10:G40) -> 60 | H41: =SUM(H10:H40) -> 2 | I41: =SUM(I10:I40) -> 0 | ... L41: =SUM(L10:L40) -> 100
G43: Neufs | I43: Rénovés
...

Sheet Juillet 2015
A1: Algérienne des Eaux | G1: Centre de : BERROUAGHIA
A2: Zone d'Alger | G2: Agence de : BERROUAGHIA
A3: Unité de Médéa
A5: Suivi Pose Compteurs
A6: Mois de Juillet 2015
A8: Date | B8: Nouveaux branchements | G8: Elimination du forfait | L8: Total (1+2)
B9: I | C9: II | D9: III | E9: IV | F9: Total (1) | G9: I | H9: II | I9: III | J9: IV | K9: Total (2)
A10: 1 | B10: 1 | F10: =SUM(B10:E10) -> 1 | H10: 1 | K10: =SUM(G10:J10) -> 1 | L10: =SUM(F10+K10) -> 2
A11: 2 | F11: =SUM(B11:E11) -> 0 | K11: =SUM(G11:J11) -> 0 | L11: =SUM(F11+K11) -> 0
A12: 3 | F12: =SUM(B12:E12) -> 0 | K12: =SUM(G12:J12) -> 0 | L12: =SUM(F12+K12) -> 0
A13: 4 | F13: =SUM(B13:E13) -> 0 | K13: =SUM(G13:J13) -> 0 | L13: =SUM(F13+K13) -> 0
A14: 5 | F14: =SUM(B14:E14) -> 0 | K14: =SUM(G14:J14) -> 0 | L14: =SUM(F14+K14) -> 0
A15: 6 | F15: =SUM(B15:E15) -> 0 | K15: =SUM(G15:J15) -> 0 | L15: =SUM(F15+K15) -> 0
A16: 7 | F16: =SUM(B16:E16) -> 0 | G16: 5 | K16: =SUM(G16:J16) -> 5 | L16: =SUM(F16+K16) -> 5
A17: 8 | F17: =SUM(B17:E17) -> 0 | G17: 8 | K17: =SUM(G17:J17) -> 8 | L17: =SUM(F17+K17) -> 8
A18: 9 | F18: =SUM(B18:E18) -> 0 | G18: 3 | K18: =SUM(G18:J18) -> 3 | L18: =SUM(F18+K18) -> 3
A19: 10 | F19: =SUM(B19:E19) -> 0 | K19: =SUM(G19:J19) -> 0 | L19: =SUM(F19+K19) -> 0
A20: 11 | F20: =SUM(B20:E20) -> 0 | K20: =SUM(G20:J20) -> 0 | L20: =SUM(F20+K20) -> 0
A21: 12 | B21: 2 | F21: =SUM(B21:E21) -> 2 | K21: =SUM(G21:J21) -> 0 | L21: =SUM(F21+K21) -> 2
A22: 13 | B22: 3 | F22: =SUM(B22:E22) -> 3 | G22: 1 | K22: =SUM(G22:J22) -> 1 | L22: =SUM(F22+K22) -> 4
A23: 14 | B23: 1 | F23: =SUM(B23:E23) -> 1 | K23: =SUM(G23:J23) -> 0 | L23: =SUM(F23+K23) -> 1
A24: 15 | B24: 1 | F24: =SUM(B24:E24) -> 1 | G24: 3 | K24: =SUM(G24:J24) -> 3 | L24: =SUM(F24+K24) -> 4
A25: 16 | F25: =SUM(B25:E25) -> 0 | G25: 4 | K25: =SUM(G25:J25) -> 4 | L25: =SUM(F25+K25) -> 4
A26: 17 | F26: =SUM(B26:E26) -> 0 | K26: =SUM(G26:J26) -> 0 | L26: =SUM(F26+K26) -> 0
A27: 18 | F27: =SUM(B27:E27) -> 0 | K27: =SUM(G27:J27) -> 0 | L27: =SUM(F27+K27) -> 0
A28: 19 | F28: =SUM(B28:E28) -> 0 | G28: 4 | K28: =SUM(G28:J28) -> 4 | L28: =SUM(F28+K28) -> 4
A29: 20 | F29: =SUM(B29:E29) -> 0 | K29: =SUM(G29:J29) -> 0 | L29: =SUM(F29+K29) -> 0
A30: 21 | F30: =SUM(B30:E30) -> 0 | K30: =SUM(G30:J30) -> 0 | L30: =SUM(F30+K30) -> 0
A31: 22 | F31: =SUM(B31:E31) -> 0 | G31: 3 | K31: =SUM(G31:J31) -> 3 | L31: =SUM(F31+K31) -> 3
A32: 23 | F32: =SUM(B32:E32) -> 0 | G32: 2 | K32: =SUM(G32:J32) -> 2 | L32: =SUM(F32+K32) -> 2
A33: 24 | F33: =SUM(B33:E33) -> 0 | K33: =SUM(G33:J33) -> 0 | L33: =SUM(F33+K33) -> 0
A34: 25 | F34: =SUM(B34:E34) -> 0 | K34: =SUM(G34:J34) -> 0 | L34: =SUM(F34+K34) -> 0
A35: 26 | B35: 1 | F35: =SUM(B35:E35) -> 1 | K35: =SUM(G35:J35) -> 0 | L35: =SUM(F35+K35) -> 1
A36: 27 | F36: =SUM(B36:E36) -> 0 | K36: =SUM(G36:J36) -> 0 | L36: =SUM(F36+K36) -> 0
A37: 28 | B37: 1 | F37: =SUM(B37:E37) -> 1 | K37: =SUM(G37:J37) -> 0 | L37: =SUM(F37+K37) -> 1
A38: 29 | B38: 1 | D38: 1 | F38: =SUM(B38:E38) -> 2 | K38: =SUM(G38:J38) -> 0 | L38: =SUM(F38+K38) -> 2
A39: 30 | B39: 2 | F39: =SUM(B39:E39) -> 2 | K39: =SUM(G39:J39) -> 0 | L39: =SUM(F39+K39) -> 2
A40: 31 | F40: =SUM(B40:E40) -> 0 | K40: =SUM(G40:J40) -> 0 | L40: =SUM(F40+K40) -> 0
B41: =SUM(B10:B40) -> 13 | C41: =SUM(C10:C40) -> 0 | D41: =SUM(D10:D40) -> 1 | E41: =SUM(E10:E40) -> 0 | F41: =SUM(F10:F40) -> 14 | G41: =SUM(G10:G40) -> 33 | H41: =SUM(H10:H40) -> 1 | I41: =SUM(I10:I40) -> 0 | ... L41: =SUM(L10:L40) -> 48
G43: Neufs | I43: Rénovés
...

Sheet Aout 2015
A1: Algérienne des Eaux | G1: Centre de : BERROUAGHIA
A2: Zone d'Alger | G2: Agence de : BERROUAGHIA
A3: Unité de Médéa
A4: Suivi Pose Compteurs
A5: Mois de Aout 2015
A6: Date | B6: Nouveaux branchements | G6: Elimination du forfait | L6: Total (1+2)
B7: I | C7: II | D7: III | E7: IV | F7: Total (1) | G7: I | H7: II | I7: III | J7: IV | K7: Total (2)
A8: 1 | F8: =SUM(B8:E8) -> 0 | K8: =SUM(G8:J8) -> 0 | L8: =SUM(F8+K8) -> 0
A9: 2 | F9: =SUM(B9:E9) -> 0 | K9: =SUM(G9:J9) -> 0 | L9: =SUM(F9+K9) -> 0
A10: 3 | B10: 4 | F10: =SUM(B10:E10) -> 4 | H10: 1 | K10: =SUM(G10:J10) -> 1 | L10: =SUM(F10+K10) -> 5
A11: 4 | F11: =SUM(B11:E11) -> 0 | K11: =SUM(G11:J11) -> 0 | L11: =SUM(F11+K11) -> 0
A12: 5 | F12: =SUM(B12:E12) -> 0 | K12: =SUM(G12:J12) -> 0 | L12: =SUM(F12+K12) -> 0
A13: 6 | D13: 1 | F13: =SUM(B13:E13) -> 1 | G13: 3 | K13: =SUM(G13:J13) -> 3 | L13: =SUM(F13+K13) -> 4
A14: 7 | F14: =SUM(B14:E14) -> 0 | K14: =SUM(G14:J14) -> 0 | L14: =SUM(F14+K14) -> 0
A15: 8 | F15: =SUM(B15:E15) -> 0 | K15: =SUM(G15:J15) -> 0 | L15: =SUM(F15+K15) -> 0
A16: 9 | F16: =SUM(B16:E16) -> 0 | K16: =SUM(G16:J16) -> 0 | L16: =SUM(F16+K16) -> 0
A17: 10 | B17: 4 | F17: =SUM(B17:E17) -> 4 | K17: =SUM(G17:J17) -> 0 | L17: =SUM(F17+K17) -> 4
A18: 11 | F18: =SUM(B18:E18) -> 0 | K18: =SUM(G18:J18) -> 0 | L18: =SUM(F18+K18) -> 0
A19: 12 | B19: 2 | F19: =SUM(B19:E19) -> 2 | K19: =SUM(G19:J19) -> 0 | L19: =SUM(F19+K19) -> 2
A20: 13 | B20: 1 | F20: =SUM(B20:E20) -> 1 | G20: 2 | K20: =SUM(G20:J20) -> 2 | L20: =SUM(F20+K20) -> 3
A21: 14 | F21: =SUM(B21:E21) -> 0 | K21: =SUM(G21:J21) -> 0 | L21: =SUM(F21+K21) -> 0
A22: 15 | F22: =SUM(B22:E22) -> 0 | K22: =SUM(G22:J22) -> 0 | L22: =SUM(F22+K22) -> 0
A23: 16 | F23: =SUM(B23:E23) -> 0 | K23: =SUM(G23:J23) -> 0 | L23: =SUM(F23+K23) -> 0
A24: 17 | F24: =SUM(B24:E24) -> 0 | K24: =SUM(G24:J24) -> 0 | L24: =SUM(F24+K24) -> 0
A25: 18 | B25: 4 | F25: =SUM(B25:E25) -> 4 | K25: =SUM(G25:J25) -> 0 | L25: =SUM(F25+K25) -> 4
A26: 19 | B26: 3 | F26: =SUM(B26:E26) -> 3 | K26: =SUM(G26:J26) -> 0 | L26: =SUM(F26+K26) -> 3
A27: 20 | E27: 1 | F27: =SUM(B27:E27) -> 1 | G27: 2 | K27: =SUM(G27:J27) -> 2 | L27: =SUM(F27+K27) -> 3
A28: 21 | F28: =SUM(B28:E28) -> 0 | K28: =SUM(G28:J28) -> 0 | L28: =SUM(F28+K28) -> 0
A29: 22 | F29: =SUM(B29:E29) -> 0 | K29: =SUM(G29:J29) -> 0 | L29: =SUM(F29+K29) -> 0
A30: 23 | B30: 4 | D30: 1 | F30: =SUM(B30:E30) -> 5 | G30: 1 | K30: =SUM(G30:J30) -> 1 | L30: =SUM(F30+K30) -> 6
A31: 24 | F31: =SUM(B31:E31) -> 0 | K31: =SUM(G31:J31) -> 0 | L31: =SUM(F31+K31) -> 0
A32: 25 | B32: 2 | F32: =SUM(B32:E32) -> 2 | G32: 4 | K32: =SUM(G32:J32) -> 4 | L32: =SUM(F32+K32) -> 6
A33: 26 | C33: 1 | F33: =SUM(B33:E33) -> 1 | G33: 1 | H33: 2 | K33: =SUM(G33:J33) -> 3 | L33: =SUM(F33+K33) -> 4
A34: 27 | B34: 1 | F34: =SUM(B34:E34) -> 1 | G34: 1 | H34: 1 | K34: =SUM(G34:J34) -> 2 | L34: =SUM(F34+K34) -> 3
A35: 28 | F35: =SUM(B35:E35) -> 0 | K35: =SUM(G35:J35) -> 0 | L35: =SUM(F35+K35) -> 0
A36: 29 | F36: =SUM(B36:E36) -> 0 | K36: =SUM(G36:J36) -> 0 | L36: =SUM(F36+K36) -> 0
A37: 30 | F37: =SUM(B37:E37) -> 0 | K37: =SUM(G37:J37) -> 0 | L37: =SUM(F37+K37) -> 0
A38: 31 | B38: 3 | F38: =SUM(B38:E38) -> 3 | G38: 2 | K38: =SUM(G38:J38) -> 2 | L38: =SUM(F38+K38) -> 5
B39: =SUM(B8:B38) -> 28 | C39: =SUM(C8:C38) -> 1 | D39: =SUM(D8:D38) -> 2 | E39: =SUM(E8:E38) -> 1 | F39: =SUM(F8:F38) -> 32 | G39: =SUM(G8:G38) -> 16 | H39: =SUM(H8:H38) -> 4 | I39: =SUM(I8:I38) -> 0 | ... L39: =SUM(L8:L38) -> 52
G41: Neufs | I41: Rénovés
...

Sheet Septembre 2015
A1: Algérienne des Eaux | G1: Centre de : BERROUAGHIA
A2: Zone d'Alger | G2: Agence de : BERROUAGHIA
A3: Unité de Médéa
A5: Suivi Pose Compteurs
A6: Mois de Septembre 2015
A8: Date | B8: Nouveaux branchements | G8: Elimination du forfait | L8: Total (1+2)
B9: I | C9: II | D9: III | E9: IV | F9: Total (1) | G9: I | H9: II | I9: III | J9: IV | K9: Total (2)
A10: 1 | B10: 1 | F10: =SUM(B10:E10) -> 1 | K10: =SUM(G10:J10) -> 0 | L10: =SUM(F10+K10) -> 1
A11: 2 | B11: 2 | F11: =SUM(B11:E11) -> 2 | K11: =SUM(G11:J11) -> 0 | L11: =SUM(F11+K11) -> 2
A12: 3 | F12: =SUM(B12:E12) -> 0 | G12: 2 | K12: =SUM(G12:J12) -> 2 | L12: =SUM(F12+K12) -> 2
A13: 4 | F13: =SUM(B13:E13) -> 0 | K13: =SUM(G13:J13) -> 0 | L13: =SUM(F13+K13) -> 0
A14: 5 | F14: =SUM(B14:E14) -> 0 | K14: =SUM(G14:J14) -> 0 | L14: =SUM(F14+K14) -> 0
A15: 6 | F15: =SUM(B15:E15) -> 0 | K15: =SUM(G15:J15) -> 0 | L15: =SUM(F15+K15) -> 0
A16: 7 | F16: =SUM(B16:E16) -> 0 | G16: 1 | K16: =SUM(G16:J16) -> 1 | L16: =SUM(F16+K16) -> 1
A17: 8 | F17: =SUM(B17:E17) -> 0 | K17: =SUM(G17:J17) -> 0 | L17: =SUM(F17+K17) -> 0
A18: 9 | B18: 1 | D18: 1 | F18: =SUM(B18:E18) -> 2 | K18: =SUM(G18:J18) -> 0 | L18: =SUM(F18+K18) -> 2
A19: 10 | B19: 1 | F19: =SUM(B19:E19) -> 1 | K19: =SUM(G19:J19) -> 0 | L19: =SUM(F19+K19) -> 1
A20: 11 | F20: =SUM(B20:E20) -> 0 | K20: =SUM(G20:J20) -> 0 | L20: =SUM(F20+K20) -> 0
A21: 12 | F21: =SUM(B21:E21) -> 0 | G21: 6 | K21: =SUM(G21:J21) -> 6 | L21: =SUM(F21+K21) -> 6
A22: 13 | B22: 1 | F22: =SUM(B22:E22) -> 1 | G22: 3 | K22: =SUM(G22:J22) -> 3 | L22: =SUM(F22+K22) -> 4
A23: 14 | F23: =SUM(B23:E23) -> 0 | G23: 4 | K23: =SUM(G23:J23) -> 4 | L23: =SUM(F23+K23) -> 4
A24: 15 | B24: 2 | F24: =SUM(B24:E24) -> 2 | K24: =SUM(G24:J24) -> 0 | L24: =SUM(F24+K24) -> 2
A25: 16 | F25: =SUM(B25:E25) -> 0 | H25: 1 | I25: 1 | K25: =SUM(G25:J25) -> 2 | L25: =SUM(F25+K25) -> 2
A26: 17 | C26: 1 | F26: =SUM(B26:E26) -> 1 | G26: 4 | H26: 1 | K26: =SUM(G26:J26) -> 5 | L26: =SUM(F26+K26) -> 6
A27: 18 | F27: =SUM(B27:E27) -> 0 | K27: =SUM(G27:J27) -> 0 | L27: =SUM(F27+K27) -> 0
A28: 19 | F28: =SUM(B28:E28) -> 0 | K28: =SUM(G28:J28) -> 0 | L28: =SUM(F28+K28) -> 0
A29: 20 | B29: 3 | F29: =SUM(B29:E29) -> 3 | H29: 1 | K29: =SUM(G29:J29) -> 1 | L29: =SUM(F29+K29) -> 4
A30: 21 | F30: =SUM(B30:E30) -> 0 | G30: 2 | H30: 1 | K30: =SUM(G30:J30) -> 3 | L30: =SUM(F30+K30) -> 3
A31: 22 | F31: =SUM(B31:E31) -> 0 | K31: =SUM(G31:J31) -> 0 | L31: =SUM(F31+K31) -> 0
A32: 23 | B32: 1 | F32: =SUM(B32:E32) -> 1 | G32: 1 | K32: =SUM(G32:J32) -> 1 | L32: =SUM(F32+K32) -> 2
A33: 24 | F33: =SUM(B33:E33) -> 0 | K33: =SUM(G33:J33) -> 0 | L33: =SUM(F33+K33) -> 0
A34: 25 | F34: =SUM(B34:E34) -> 0 | K34: =SUM(G34:J34) -> 0 | L34: =SUM(F34+K34) -> 0
A35: 26 | F35: =SUM(B35:E35) -> 0 | K35: =SUM(G35:J35) -> 0 | L35: =SUM(F35+K35) -> 0
A36: 27 | F36: =SUM(B36:E36) -> 0 | K36: =SUM(G36:J36) -> 0 | L36: =SUM(F36+K36) -> 0
A37: 28 | B37: 7 | D37: 2 | F37: =SUM(B37:E37) -> 9 | K37: =SUM(G37:J37) -> 0 | L37: =SUM(F37+K37) -> 9
A38: 29 | F38: =SUM(B38:E38) -> 0 | K38: =SUM(G38:J38) -> 0 | L38: =SUM(F38+K38) -> 0
A39: 30 | F39: =SUM(B39:E39) -> 0 | K39: =SUM(G39:J39) -> 0 | L39: =SUM(F39+K39) -> 0
A40: 31 | F40: =SUM(B40:E40) -> 0 | K40: =SUM(G40:J40) -> 0 | L40: =SUM(F40+K40) -> 0
B41: =SUM(B10:B40) -> 19 | C41: =SUM(C10:C40) -> 1 | D41: =SUM(D10:D40) -> 3 | E41: =SUM(E10:E40) -> 0 | F41: =SUM(F10:F40) -> 23 | G41: =SUM(G10:G40) -> 23 | H41: =SUM(H10:H40) -> 4 | I41: =SUM(I10:I40) -> 1 | ... L41: =SUM(L10:L40) -> 51
G43: Neufs | I43: Rénovés
...

Sheet Octobre 2015
A1: Algérienne des Eaux | G1: Centre de : BERROUAGHIA
A2: Zone d'Alger | G2: Agence de : BERROUAGHIA
A3: Unité de Médéa
A5: Suivi Pose Compteurs
A6: Mois de Octobre 2015
A8: Date | B8: Nouveaux branchements | G8: Elimination du forfait | L8: Total (1+2)
B9: I | C9: II | D9: III | E9: IV | F9: Total (1) | G9: I | H9: II | I9: III | J9: IV | K9: Total (2)
A10: 1 | F10: =SUM(B10:E10) -> 0 | K10: =SUM(G10:J10) -> 0 | L10: =SUM(F10+K10) -> 0
A11: 2 | F11: =SUM(B11:E11) -> 0 | K11: =SUM(G11:J11) -> 0 | L11: =SUM(F11+K11) -> 0
A12: 3 | F12: =SUM(B12:E12) -> 0 | K12: =SUM(G12:J12) -> 0 | L12: =SUM(F12+K12) -> 0
A13: 4 | B13: 2 | F13: =SUM(B13:E13) -> 2 | G13: 1 | K13: =SUM(G13:J13) -> 1 | L13: =SUM(F13+K13) -> 3
A14: 5 | F14: =SUM(B14:E14) -> 0 | K14: =SUM(G14:J14) -> 0 | L14: =SUM(F14+K14) -> 0
A15: 6 | F15: =SUM(B15:E15) -> 0 | K15: =SUM(G15:J15) -> 0 | L15: =SUM(F15+K15) -> 0
A16: 7 | B16: 1 | F16: =SUM(B16:E16) -> 1 | K16: =SUM(G16:J16) -> 0 | L16: =SUM(F16+K16) -> 1
A17: 8 | F17: =SUM(B17:E17) -> 0 | G17: 7 | J17: 1 | K17: =SUM(G17:J17) -> 8 | L17: =SUM(F17+K17) -> 8
A18: 9 | F18: =SUM(B18:E18) -> 0 | K18: =SUM(G18:J18) -> 0 | L18: =SUM(F18+K18) -> 0
A19: 10 | F19: =SUM(B19:E19) -> 0 | K19: =SUM(G19:J19) -> 0 | L19: =SUM(F19+K19) -> 0
A20: 11 | F20: =SUM(B20:E20) -> 0 | G20: 1 | K20: =SUM(G20:J20) -> 1 | L20: =SUM(F20+K20) -> 1
A21: 12 | F21: =SUM(B21:E21) -> 0 | K21: =SUM(G21:J21) -> 0 | L21: =SUM(F21+K21) -> 0
A22: 13 | F22: =SUM(B22:E22) -> 0 | K22: =SUM(G22:J22) -> 0 | L22: =SUM(F22+K22) -> 0
A23: 14 | F23: =SUM(B23:E23) -> 0 | G23: 4 | K23: =SUM(G23:J23) -> 4 | L23: =SUM(F23+K23) -> 4
A24: 15 | F24: =SUM(B24:E24) -> 0 | K24: =SUM(G24:J24) -> 0 | L24: =SUM(F24+K24) -> 0
A25: 16 | F25: =SUM(B25:E25) -> 0 | K25: =SUM(G25:J25) -> 0 | L25: =SUM(F25+K25) -> 0
A26: 17 | F26: =SUM(B26:E26) -> 0 | K26: =SUM(G26:J26) -> 0 | L26: =SUM(F26+K26) -> 0
A27: 18 | B27: 2 | F27: =SUM(B27:E27) -> 2 | K27: =SUM(G27:J27) -> 0 | L27: =SUM(F27+K27) -> 2
A28: 19 | F28: =SUM(B28:E28) -> 0 | K28: =SUM(G28:J28) -> 0 | L28: =SUM(F28+K28) -> 0
A29: 20 | B29: 2 | F29: =SUM(B29:E29) -> 2 | K29: =SUM(G29:J29) -> 0 | L29: =SUM(F29+K29) -> 2
A30: 21 | F30: =SUM(B30:E30) -> 0 | G30: 4 | K30: =SUM(G30:J30) -> 4 | L30: =SUM(F30+K30) -> 4
A31: 22 | F31: =SUM(B31:E31) -> 0 | G31: 5 | K31: =SUM(G31:J31) -> 5 | L31: =SUM(F31+K31) -> 5
A32: 23 | F32: =SUM(B32:E32) -> 0 | K32: =SUM(G32:J32) -> 0 | L32: =SUM(F32+K32) -> 0
A33: 24 | F33: =SUM(B33:E33) -> 0 | K33: =SUM(G33:J33) -> 0 | L33: =SUM(F33+K33) -> 0
A34: 25 | B34: 3 | F34: =SUM(B34:E34) -> 3 | G34: 5 | K34: =SUM(G34:J34) -> 5 | L34: =SUM(F34+K34) -> 8
A35: 26 | F35: =SUM(B35:E35) -> 0 | G35: 3 | K35: =SUM(G35:J35) -> 3 | L35: =SUM(F35+K35) -> 3
A36: 27 | B36: 5 | F36: =SUM(B36:E36) -> 5 | G36: 2 | K36: =SUM(G36:J36) -> 2 | L36: =SUM(F36+K36) -> 7
A37: 28 | F37: =SUM(B37:E37) -> 0 | G37: 3 | K37: =SUM(G37:J37) -> 3 | L37: =SUM(F37+K37) -> 3
A38: 29 | F38: =SUM(B38:E38) -> 0 | K38: =SUM(G38:J38) -> 0 | L38: =SUM(F38+K38) -> 0
A39: 30 | F39: =SUM(B39:E39) -> 0 | K39: =SUM(G39:J39) -> 0 | L39: =SUM(F39+K39) -> 0
A40: 31 | F40: =SUM(B40:E40) -> 0 | K40: =SUM(G40:J40) -> 0 | L40: =SUM(F40+K40) -> 0
B41: =SUM(B10:B40) -> 15 | C41: =SUM(C10:C40) -> 0 | D41: =SUM(D10:D40) -> 0 | E41: =SUM(E10:E40) -> 0 | F41: =SUM(F10:F40) -> 15 | G41: =SUM(G10:G40) -> 35 | H41: =SUM(H10:H40) -> 0 | I41: =SUM(I10:I40) -> 0 | ... L41: =SUM(L10:L40) -> 51
G43: Neufs | I43: Rénovés
...

Sheet Novembre 2015
A1: Algérienne des Eaux | G1: Centre de : BERROUAGHIA
A2: Zone d'Alger | G2: Agence de : BERROUAGHIA
A3: Unité de Médéa
A5: Suivi Pose Compteurs
A6: Mois de Novembre 2015
A8: Date | B8: Nouveaux branchements | G8: Elimination du forfait | L8: Total (1+2)
B9: I | C9: II | D9: III | E9: IV | F9: Total (1) | G9: I | H9: II | I9: III | J9: IV | K9: Total (2)
A10: 1 | F10: =SUM(B10:E10) -> 0 | K10: =SUM(G10:J10) -> 0 | L10: =SUM(F10+K10) -> 0
A11: 2 | F11: =SUM(B11:E11) -> 0 | K11: =SUM(G11:J11) -> 0 | L11: =SUM(F11+K11) -> 0
A12: 3 | F12: =SUM(B12:E12) -> 0 | K12: =SUM(G12:J12) -> 0 | L12: =SUM(F12+K12) -> 0
A13: 4 | B13: 1 | F13: =SUM(B13:E13) -> 1 | K13: =SUM(G13:J13) -> 0 | L13: =SUM(F13+K13) -> 1
A14: 5 | F14: =SUM(B14:E14) -> 0 | G14: 2 | I14: 1 | K14: =SUM(G14:J14) -> 3 | L14: =SUM(F14+K14) -> 3
A15: 6 | F15: =SUM(B15:E15) -> 0 | K15: =SUM(G15:J15) -> 0 | L15: =SUM(F15+K15) -> 0
A16: 7 | F16: =SUM(B16:E16) -> 0 | K16: =SUM(G16:J16) -> 0 | L16: =SUM(F16+K16) -> 0
A17: 8 | B17: 2 | F17: =SUM(B17:E17) -> 2 | K17: =SUM(G17:J17) -> 0 | L17: =SUM(F17+K17) -> 2
A18: 9 | F18: =SUM(B18:E18) -> 0 | K18: =SUM(G18:J18) -> 0 | L18: =SUM(F18+K18) -> 0
A19: 10 | F19: =SUM(B19:E19) -> 0 | K19: =SUM(G19:J19) -> 0 | L19: =SUM(F19+K19) -> 0
A20: 11 | F20: =SUM(B20:E20) -> 0 | K20: =SUM(G20:J20) -> 0 | L20: =SUM(F20+K20) -> 0
A21: 12 | F21: =SUM(B21:E21) -> 0 | G21: 9 | H21: 1 | K21: =SUM(G21:J21) -> 10 | L21: =SUM(F21+K21) -> 10
A22: 13 | F22: =SUM(B22:E22) -> 0 | K22: =SUM(G22:J22) -> 0 | L22: =SUM(F22+K22) -> 0
A23: 14 | F23: =SUM(B23:E23) -> 0 | K23: =SUM(G23:J23) -> 0 | L23: =SUM(F23+K23) -> 0
A24: 15 | F24: =SUM(B24:E24) -> 0 | K24: =SUM(G24:J24) -> 0 | L24: =SUM(F24+K24) -> 0
A25: 16 | F25: =SUM(B25:E25) -> 0 | K25: =SUM(G25:J25) -> 0 | L25: =SUM(F25+K25) -> 0
A26: 17 | F26: =SUM(B26:E26) -> 0 | K26: =SUM(G26:J26) -> 0 | L26: =SUM(F26+K26) -> 0
A27: 18 | F27: =SUM(B27:E27) -> 0 | K27: =SUM(G27:J27) -> 0 | L27: =SUM(F27+K27) -> 0
A28: 19 | F28: =SUM(B28:E28) -> 0 | I28: 1 | K28: =SUM(G28:J28) -> 1 | L28: =SUM(F28+K28) -> 1
A29: 20 | F29: =SUM(B29:E29) -> 0 | K29: =SUM(G29:J29) -> 0 | L29: =SUM(F29+K29) -> 0
A30: 21 | F30: =SUM(B30:E30) -> 0 | K30: =SUM(G30:J30) -> 0 | L30: =SUM(F30+K30) -> 0
A31: 22 | D31: 1 | F31: =SUM(B31:E31) -> 1 | G31: 1 | I31: 1 | K31: =SUM(G31:J31) -> 2 | L31: =SUM(F31+K31) -> 3
A32: 23 | B32: 1 | F32: =SUM(B32:E32) -> 1 | K32: =SUM(G32:J32) -> 0 | L32: =SUM(F32+K32) -> 1
A33: 24 | F33: =SUM(B33:E33) -> 0 | K33: =SUM(G33:J33) -> 0 | L33: =SUM(F33+K33) -> 0
A34: 25 | F34: =SUM(B34:E34) -> 0 | I34: 1 | K34: =SUM(G34:J34) -> 1 | L34: =SUM(F34+K34) -> 1
A35: 26 | F35: =SUM(B35:E35) -> 0 | G35: 2 | K35: =SUM(G35:J35) -> 2 | L35: =SUM(F35+K35) -> 2
A36: 27 | F36: =SUM(B36:E36) -> 0 | K36: =SUM(G36:J36) -> 0 | L36: =SUM(F36+K36) -> 0
A37: 28 | F37: =SUM(B37:E37) -> 0 | K37: =SUM(G37:J37) -> 0 | L37: =SUM(F37+K37) -> 0
A38: 29 | F38: =SUM(B38:E38) -> 0 | G38: 6 | K38: =SUM(G38:J38) -> 6 | L38: =SUM(F38+K38) -> 6
A39: 30 | F39: =SUM(B39:E39) -> 0 | G39: 2 | K39: =SUM(G39:J39) -> 2 | L39: =SUM(F39+K39) -> 2
A40: 31 | F40: =SUM(B40:E40) -> 0 | K40: =SUM(G40:J40) -> 0 | L40: =SUM(F40+K40) -> 0
B41: =SUM(B10:B40) -> 4 | C41: =SUM(C10:C40) -> 0 | D41: =SUM(D10:D40) -> 1 | E41: =SUM(E10:E40) -> 0 | F41: =SUM(F10:F40) -> 5 | G41: =SUM(G10:G40) -> 22 | H41: =SUM(H10:H40) -> 1 | I41: =SUM(I10:I40) -> 4 | ... L41: =SUM(L10:L40) -> 32
G43: Neufs | I43: Rénovés
...

Sheet Decembre 2015
A1: Algérienne des Eaux | G1: Centre de : BERROUAGHIA
A2: Zone d'Alger | G2: Agence de : BERROUAGHIA
A3: Unité de Médéa
A5: Suivi Pose Compteurs
A6: Mois de Decembre 2015
A8: Date | B8: Nouveaux branchements | G8: Elimination du forfait | L8: Total (1+2)
B9: I | C9: II | D9: III | E9: IV | F9: Total (1) | G9: I | H9: II | I9: III | J9: IV | K9: Total (2)
A10: 1 | F10: =SUM(B10:E10) -> 0 | K10: =SUM(G10:J10) -> 0 | L10: =SUM(F10+K10) -> 0
A11: 2 | F11: =SUM(B11:E11) -> 0 | K11: =SUM(G11:J11) -> 0 | L11: =SUM(F11+K11) -> 0
A12: 3 | B12: 2 | F12: =SUM(B12:E12) -> 2 | K12: =SUM(G12:J12) -> 0 | L12: =SUM(F12+K12) -> 2
A13: 4 | F13: =SUM(B13:E13) -> 0 | K13: =SUM(G13:J13) -> 0 | L13: =SUM(F13+K13) -> 0
A14: 5 | F14: =SUM(B14:E14) -> 0 | K14: =SUM(G14:J14) -> 0 | L14: =SUM(F14+K14) -> 0
A15: 6 | B15: 5 | E15: 1 | F15: =SUM(B15:E15) -> 6 | K15: =SUM(G15:J15) -> 0 | L15: =SUM(F15+K15) -> 6
A16: 7 | B16: 5 | F16: =SUM(B16:E16) -> 5 | H16: 1 | J16: 1 | K16: =SUM(G16:J16) -> 2 | L16: =SUM(F16+K16) -> 7
A17: 8 | B17: 4 | F17: =SUM(B17:E17) -> 4 | K17: =SUM(G17:J17) -> 0 | L17: =SUM(F17+K17) -> 4
A18: 9 | F18: =SUM(B18:E18) -> 0 | K18: =SUM(G18:J18) -> 0 | L18: =SUM(F18+K18) -> 0
A19: 10 | F19: =SUM(B19:E19) -> 0 | G19: 10 | K19: =SUM(G19:J19) -> 10 | L19: =SUM(F19+K19) -> 10
A20: 11 | F20: =SUM(B20:E20) -> 0 | K20: =SUM(G20:J20) -> 0 | L20: =SUM(F20+K20) -> 0
A21: 12 | F21: =SUM(B21:E21) -> 0 | K21: =SUM(G21:J21) -> 0 | L21: =SUM(F21+K21) -> 0
A22: 13 | F22: =SUM(B22:E22) -> 0 | K22: =SUM(G22:J22) -> 0 | L22: =SUM(F22+K22) -> 0
A23: 14 | B23: 1 | F23: =SUM(B23:E23) -> 1 | G23: 2 | K23: =SUM(G23:J23) -> 2 | L23: =SUM(F23+K23) -> 3
A24: 15 | F24: =SUM(B24:E24) -> 0 | K24: =SUM(G24:J24) -> 0 | L24: =SUM(F24+K24) -> 0
A25: 16 | B25: 1 | C25: 1 | F25: =SUM(B25:E25) -> 2 | G25: 2 | K25: =SUM(G25:J25) -> 2 | L25: =SUM(F25+K25) -> 4
A26: 17 | C26: 1 | F26: =SUM(B26:E26) -> 1 | G26: 3 | K26: =SUM(G26:J26) -> 3 | L26: =SUM(F26+K26) -> 4
A27: 18 | F27: =SUM(B27:E27) -> 0 | K27: =SUM(G27:J27) -> 0 | L27: =SUM(F27+K27) -> 0
A28: 19 | F28: =SUM(B28:E28) -> 0 | K28: =SUM(G28:J28) -> 0 | L28: =SUM(F28+K28) -> 0
A29: 20 | F29: =SUM(B29:E29) -> 0 | K29: =SUM(G29:J29) -> 0 | L29: =SUM(F29+K29) -> 0
A30: 21 | F30: =SUM(B30:E30) -> 0 | G30: 4 | K30: =SUM(G30:J30) -> 4 | L30: =SUM(F30+K30) -> 4
A31: 22 | B31: 4 | F31: =SUM(B31:E31) -> 4 | K31: =SUM(G31:J31) -> 0 | L31: =SUM(F31+K31) -> 4
A32: 23 | F32: =SUM(B32:E32) -> 0 | G32: 10 | H32: 1 | K32: =SUM(G32:J32) -> 11 | L32: =SUM(F32+K32) -> 11
A33: 24 | F33: =SUM(B33:E33) -> 0 | K33: =SUM(G33:J33) -> 0 | L33: =SUM(F33+K33) -> 0
A34: 25 | F34: =SUM(B34:E34) -> 0 | K34: =SUM(G34:J34) -> 0 | L34: =SUM(F34+K34) -> 0
A35: 26 | F35: =SUM(B35:E35) -> 0 | K35: =SUM(G35:J35) -> 0 | L35: =SUM(F35+K35) -> 0
A36: 27 | F36: =SUM(B36:E36) -> 0 | G36: 7 | H36: 1 | K36: =SUM(G36:J36) -> 8 | L36: =SUM(F36+K36) -> 8
A37: 28 | F37: =SUM(B37:E37) -> 0 | G37: 3 | K37: =SUM(G37:J37) -> 3 | L37: =SUM(F37+K37) -> 3
A38: 29 | F38: =SUM(B38:E38) -> 0 | G38: 2 | H38: 1 | I38: 1 | K38: =SUM(G38:J38) -> 4 | L38: =SUM(F38+K38) -> 4
A39: 30 | F39: =SUM(B39:E39) -> 0 | G39: 6 | H39: 1 | K39: =SUM(G39:J39) -> 7 | L39: =SUM(F39+K39) -> 7
A40: 31 | B40: 5 | F40: =SUM(B40:E40) -> 5 | G40: 4 | K40: =SUM(G40:J40) -> 4 | L40: =SUM(F40+K40) -> 9
B41: =SUM(B10:B40) -> 27 | C41: =SUM(C10:C40) -> 2 | D41: =SUM(D10:D40) -> 0 | E41: =SUM(E10:E40) -> 1 | F41: =SUM(F10:F40) -> 30 | G41: =SUM(G10:G40) -> 53 | H41: =SUM(H10:H40) -> 5 | I41: =SUM(I10:I40) -> 1 | ... L41: =SUM(L10:L40) -> 90
G43: Neufs | I43: Rénovés
...

Sheet annee 2015
A1: Algérienne des Eaux | G1: Centre de : BERROUAGHIA
A2: Zone d'Alger | G2: Agence de : BERROUAGHIA
A3: Unité de Médéa
A5: Suivi Pose Compteurs
A6: annee 2015
A8: Date | B8: Nouveaux branchements | G8: Elimination du forfait | L8: Total (1+2)
B9: I | C9: II | D9: III | E9: IV | F9: Total (1) | G9: I | H9: II | I9: III | J9: IV | K9: Total (2)
A10: 1 | B10: ='JANVIER 2015'!B9+'FEVRIER 2015'!B8+'Mars 2015'!B10+'Avril 2015'!B10+'Mai 2015'!B10+'Juin 2015'!B10+'Juillet 2015'!B10+'Aout 2015'!B8+'Septembre 2015'!B10+'Octobre 2015'!B10+'Novembre 2015'!B10+'Decembre 2015'!B10 -> 5 | C10: ='JANVIER 2015'!C9+'FEVRIER 2015'!C8+'Mars 2015'!C10+'Avril 2015'!C10+'Mai 2015'!C10+'Juin 2015'!C10+'Juillet 2015'!C10+'Aout 2015'!C8+'Septembre 2015'!C10+'Octobre 2015'!C10+'Novembre 2015'!C10+'Decembre 2015'!C10 -> 0 | D10: ='JANVIER 2015'!D9+'FEVRIER 2015'!D8+'Mars 2015'!D10+'Avril 2015'!D10+'Mai 2015'!D10+'Juin 2015'!D10+'Juillet 2015'!D10+'Aout 2015'!D8+'Septembre 2015'!D10+'Octobre 2015'!D10+'Novembre 2015'!D10+'Decembre 2015'!D10 -> 0 | E10: ='JANVIER 2015'!E9+'FEVRIER 2015'!E8+'Mars 2015'!E10+'Avril 2015'!E10+'Mai 2015'!E10+'Juin 2015'!E10+'Juillet 2015'!E10+'Aout 2015'!E8+'Septembre 2015'!E10+'Octobre 2015'!E10+'Novembre 2015'!E10+'Decembre 2015'!E10 -> 0 | F10: =SUM(B10:E10) -> 5 | G10: ='JANVIER 2015'!G9+'FEVRIER 2015'!G8+'Mars 2015'!G10+'Avril 2015'!G10+'Mai 2015'!G10+'Juin 2015'!G10+'Juillet 2015'!G10+'Aout 2015'!G8+'Septembre 2015'!G10+'Octobre 2015'!G10+'Novembre 2015'!G10+'Decembre 2015'!G10 -> 3 | H10: ='JANVIER 2015'!H9+'FEVRIER 2015'!H8+'Mars 2015'!H10+'Avril 2015'!H10+'Mai 2015'!H10+'Juin 2015'!H10+'Juillet 2015'!H10+'Aout 2015'!H8+'Septembre 2015'!H10+'Octobre 2015'!H10+'Novembre 2015'!H10+'Decembre 2015'!H10 -> 1 | I10: ='JANVIER 2015'!I9+'FEVRIER 2015'!I8+'Mars 2015'!I10+'Avril 2015'!I10+'Mai 2015'!I10+'Juin 2015'!I10+'Juillet 2015'!I10+'Aout 2015'!I8+'Septembre 2015'!I10+'Octobre 2015'!I10+'Novembre 2015'!I10+'Decembre 2015'!I10 -> 0 | J10: ='JANVIER 2015'!J9+'FEVRIER 2015'!J8+'Mars 2015'!J10+'Avril 2015'!J10+'Mai 2015'!J10+'Juin 2015'!J10+'Juillet 2015'!J10+'Aout 2015'!J8+'Septembre 2015'!J10+'Octobre 2015'!J10+'Novembre 2015'!J10+'Decembre 2015'!J10 -> 0 | K10: =SUM(G10:J10) -> 4 | L10: =SUM(F10+K10) -> 9
A11: 2 | B11: ='JANVIER 2015'!B10+'FEVRIER 2015'!B9+'Mars 2015'!B11+'Avril 2015'!B11+'Mai 2015'!B11+'Juin 2015'!B11+'Juillet 2015'!B11+'Aout 2015'!B9+'Septembre 2015'!B11+'Octobre 2015'!B11+'Novembre 2015'!B11+'Decembre 2015'!B11 -> 23 | C11: ='JANVIER 2015'!C10+'FEVRIER 2015'!C9+'Mars 2015'!C11+'Avril 2015'!C11+'Mai 2015'!C11+'Juin 2015'!C11+'Juillet 2015'!C11+'Aout 2015'!C9+'Septembre 2015'!C11+'Octobre 2015'!C11+'Novembre 2015'!C11+'Decembre 2015'!C11 -> 0 | D11: ='JANVIER 2015'!D10+'FEVRIER 2015'!D9+'Mars 2015'!D11+'Avril 2015'!D11+'Mai 2015'!D11+'Juin 2015'!D11+'Juillet 2015'!D11+'Aout 2015'!D9+'Septembre 2015'!D11+'Octobre 2015'!D11+'Novembre 2015'!D11+'Decembre 2015'!D11 -> 2 | E11: ='JANVIER 2015'!E10+'FEVRIER 2015'!E9+'Mars 2015'!E11+'Avril 2015'!E11+'Mai 2015'!E11+'Juin 2015'!E11+'Juillet 2015'!E11+'Aout 2015'!E9+'Septembre 2015'!E11+'Octobre 2015'!E11+'Novembre 2015'!E11+'Decembre 2015'!E11 -> 0 | F11: =SUM(B11:E11) -> 25 | G11: ='JANVIER 2015'!G10+'FEVRIER 2015'!G9+'Mars 2015'!G11+'Avril 2015'!G11+'Mai 2015'!G11+'Juin 2015'!G11+'Juillet 2015'!G11+'Aout 2015'!G9+'Septembre 2015'!G11+'Octobre 2015'!G11+'Novembre 2015'!G11+'Decembre 2015'!G11 -> 3 | H11: ='JANVIER 2015'!H10+'FEVRIER 2015'!H9+'Mars 2015'!H11+'Avril 2015'!H11+'Mai 2015'!H11+'Juin 2015'!H11+'Juillet 2015'!H11+'Aout 2015'!H9+'Septembre 2015'!H11+'Octobre 2015'!H11+'Novembre 2015'!H11+'Decembre 2015'!H11 -> 0 | I11: ='JANVIER 2015'!I10+'FEVRIER 2015'!I9+'Mars 2015'!I11+'Avril 2015'!I11+'Mai 2015'!I11+'Juin 2015'!I11+'Juillet 2015'!I11+'Aout 2015'!I9+'Septembre 2015'!I11+'Octobre 2015'!I11+'Novembre 2015'!I11+'Decembre 2015'!I11 -> 0 | J11: ='JANVIER 2015'!J10+'FEVRIER 2015'!J9+'Mars 2015'!J11+'Avril 2015'!J11+'Mai 2015'!J11+'Juin 2015'!J11+'Juillet 2015'!J11+'Aout 2015'!J9+'Septembre 2015'!J11+'Octobre 2015'!J11+'Novembre 2015'!J11+'Decembre 2015'!J11 -> 0 | K11: =SUM(G11:J11) -> 3 | L11: =SUM(F11+K11) -> 28
A12: 3 | B12: ='JANVIER 2015'!B11+'FEVRIER 2015'!B10+'Mars 2015'!B12+'Avril 2015'!B12+'Mai 2015'!B12+'Juin 2015'!B12+'Juillet 2015'!B12+'Aout 2015'!B10+'Septembre 2015'!B12+'Octobre 2015'!B12+'Novembre 2015'!B12+'Decembre 2015'!B12 -> 15 | C12: ='JANVIER 2015'!C11+'FEVRIER 2015'!C10+'Mars 2015'!C12+'Avril 2015'!C12+'Mai 2015'!C12+'Juin 2015'!C12+'Juillet 2015'!C12+'Aout 2015'!C10+'Septembre 2015'!C12+'Octobre 2015'!C12+'Novembre 2015'!C12+'Decembre 2015'!C12 -> 0 | D12: ='JANVIER 2015'!D11+'FEVRIER 2015'!D10+'Mars 2015'!D12+'Avril 2015'!D12+'Mai 2015'!D12+'Juin 2015'!D12+'Juillet 2015'!D12+'Aout 2015'!D10+'Septembre 2015'!D12+'Octobre 2015'!D12+'Novembre 2015'!D12+'Decembre 2015'!D12 -> 1 | E12: ='JANVIER 2015'!E11+'FEVRIER 2015'!E10+'Mars 2015'!E12+'Avril 2015'!E12+'Mai 2015'!E12+'Juin 2015'!E12+'Juillet 2015'!E12+'Aout 2015'!E10+'Septembre 2015'!E12+'Octobre 2015'!E12+'Novembre 2015'!E12+'Decembre 2015'!E12 -> 0 | F12: =SUM(B12:E12) -> 16 | G12: ='JANVIER 2015'!G11+'FEVRIER 2015'!G10+'Mars 2015'!G12+'Avril 2015'!G12+'Mai 2015'!G12+'Juin 2015'!G12+'Juillet 2015'!G12+'Aout 2015'!G10+'Septembre 2015'!G12+'Octobre 2015'!G12+'Novembre 2015'!G12+'Decembre 2015'!G12 -> 3 | H12: ='JANVIER 2015'!H11+'FEVRIER 2015'!H10+'Mars 2015'!H12+'Avril 2015'!H12+'Mai 2015'!H12+'Juin 2015'!H12+'Juillet 2015'!H12+'Aout 2015'!H10+'Septembre 2015'!H12+'Octobre 2015'!H12+'Novembre 2015'!H12+'Decembre 2015'!H12 -> 1 | I12: ='JANVIER 2015'!I11+'FEVRIER 2015'!I10+'Mars 2015'!I12+'Avril 2015'!I12+'Mai 2015'!I12+'Juin 2015'!I12+'Juillet 2015'!I12+'Aout 2015'!I10+'Septembre 2015'!I12+'Octobre 2015'!I12+'Novembre 2015'!I12+'Decembre 2015'!I12 -> 1 | J12: ='JANVIER 2015'!J11+'FEVRIER 2015'!J10+'Mars 2015'!J12+'Avril 2015'!J12+'Mai 2015'!J12+'Juin 2015'!J12+'Juillet 2015'!J12+'Aout 2015'!J10+'Septembre 2015'!J12+'Octobre 2015'!J12+'Novembre 2015'!J12+'Decembre 2015'!J12 -> 0 | K12: =SUM(G12:J12) -> 5 | L12: =SUM(F12+K12) -> 21
A13: 4 | B13: ='JANVIER 2015'!B12+'FEVRIER 2015'!B11+'Mars 2015'!B13+'Avril 2015'!B13+'Mai 2015'!B13+'Juin 2015'!B13+'Juillet 2015'!B13+'Aout 2015'!B11+'Septembre 2015'!B13+'Octobre 2015'!B13+'Novembre 2015'!B13+'Decembre 2015'!B13 -> 4 | C13: ='JANVIER 2015'!C12+'FEVRIER 2015'!C11+'Mars 2015'!C13+'Avril 2015'!C13+'Mai 2015'!C13+'Juin 2015'!C13+'Juillet 2015'!C13+'Aout 2015'!C11+'Septembre 2015'!C13+'Octobre 2015'!C13+'Novembre 2015'!C13+'Decembre 2015'!C13 -> 0 | D13: ='JANVIER 2015'!D12+'FEVRIER 2015'!D11+'Mars 2015'!D13+'Avril 2015'!D13+'Mai 2015'!D13+'Juin 2015'!D13+'Juillet 2015'!D13+'Aout 2015'!D11+'Septembre 2015'!D13+'Octobre 2015'!D13+'Novembre 2015'!D13+'Decembre 2015'!D13 -> 2 | E13: ='JANVIER 2015'!E12+'FEVRIER 2015'!E11+'Mars 2015'!E13+'Avril 2015'!E13+'Mai 2015'!E13+'Juin 2015'!E13+'Juillet 2015'!E13+'Aout 2015'!E11+'Septembre 2015'!E13+'Octobre 2015'!E13+'Novembre 2015'!E13+'Decembre 2015'!E13 -> 1 | F13: =SUM(B13:E13) -> 7 | G13: ='JANVIER 2015'!G12+'FEVRIER 2015'!G11+'Mars 2015'!G13+'Avril 2015'!G13+'Mai 2015'!G13+'Juin 2015'!G13+'Juillet 2015'!G13+'Aout 2015'!G11+'Septembre 2015'!G13+'Octobre 2015'!G13+'Novembre 2015'!G13+'Decembre 2015'!G13 -> 12 | H13: ='JANVIER 2015'!H12+'FEVRIER 2015'!H11+'Mars 2015'!H13+'Avril 2015'!H13+'Mai 2015'!H13+'Juin 2015'!H13+'Juillet 2015'!H13+'Aout 2015'!H11+'Septembre 2015'!H13+'Octobre 2015'!H13+'Novembre 2015'!H13+'Decembre 2015'!H13 -> 0 | I13: ='JANVIER 2015'!I12+'FEVRIER 2015'!I11+'Mars 2015'!I13+'Avril 2015'!I13+'Mai 2015'!I13+'Juin 2015'!I13+'Juillet 2015'!I13+'Aout 2015'!I11+'Septembre 2015'!I13+'Octobre 2015'!I13+'Novembre 2015'!I13+'Decembre 2015'!I13 -> 0 | J13: ='JANVIER 2015'!J12+'FEVRIER 2015'!J11+'Mars 2015'!J13+'Avril 2015'!J13+'Mai 2015'!J13+'Juin 2015'!J13+'Juillet 2015'!J13+'Aout 2015'!J11+'Septembre 2015'!J13+'Octobre 2015'!J13+'Novembre 2015'!J13+'Decembre 2015'!J13 -> 0 | K13: =SUM(G13:J13) -> 12 | L13: =SUM(F13+K13) -> 19
A14: 5 | B14: ='JANVIER 2015'!B13+'FEVRIER 2015'!B12+'Mars 2015'!B14+'Avril 2015'!B14+'Mai 2015'!B14+'Juin 2015'!B14+'Juillet 2015'!B14+'Aout 2015'!B12+'Septembre 2015'!B14+'Octobre 2015'!B14+'Novembre 2015'!B14+'Decembre 2015'!B14 -> 1 | C14: ='JANVIER 2015'!C13+'FEVRIER 2015'!C12+'Mars 2015'!C14+'Avril 2015'!C14+'Mai 2015'!C14+'Juin 2015'!C14+'Juillet 2015'!C14+'Aout 2015'!C12+'Septembre 2015'!C14+'Octobre 2015'!C14+'Novembre 2015'!C14+'Decembre 2015'!C14 -> 0 | D14: ='JANVIER 2015'!D13+'FEVRIER 2015'!D12+'Mars 2015'!D14+'Avril 2015'!D14+'Mai 2015'!D14+'Juin 2015'!D14+'Juillet 2015'!D14+'Aout 2015'!D12+'Septembre 2015'!D14+'Octobre 2015'!D14+'Novembre 2015'!D14+'Decembre 2015'!D14 -> 0 | E14: ='JANVIER 2015'!E13+'FEVRIER 2015'!E12+'Mars 2015'!E14+'Avril 2015'!E14+'Mai 2015'!E14+'Juin 2015'!E14+'Juillet 2015'!E14+'Aout 2015'!E12+'Septembre 2015'!E14+'Octobre 2015'!E14+'Novembre 2015'!E14+'Decembre 2015'!E14 -> 0 | F14: =SUM(B14:E14) -> 1 | G14: ='JANVIER 2015'!G13+'FEVRIER 2015'!G12+'Mars 2015'!G14+'Avril 2015'!G14+'Mai 2015'!G14+'Juin 2015'!G14+'Juillet 2015'!G14+'Aout 2015'!G12+'Septembre 2015'!G14+'Octobre 2015'!G14+'Novembre 2015'!G14+'Decembre 2015'!G14 -> 10 | H14: ='JANVIER 2015'!H13+'FEVRIER 2015'!H12+'Mars 2015'!H14+'Avril 2015'!H14+'Mai 2015'!H14+'Juin 2015'!H14+'Juillet 2015'!H14+'Aout 2015'!H12+'Septembre 2015'!H14+'Octobre 2015'!H14+'Novembre 2015'!H14+'Decembre 2015'!H14 -> 0 | I14: ='JANVIER 2015'!I13+'FEVRIER 2015'!I12+'Mars 2015'!I14+'Avril 2015'!I14+'Mai 2015'!I14+'Juin 2015'!I14+'Juillet 2015'!I14+'Aout 2015'!I12+'Septembre 2015'!I14+'Octobre 2015'!I14+'Novembre 2015'!I14+'Decembre 2015'!I14 -> 1 | J14: ='JANVIER 2015'!J13+'FEVRIER 2015'!J12+'Mars 2015'!J14+'Avril 2015'!J14+'Mai 2015'!J14+'Juin 2015'!J14+'Juillet 2015'!J14+'Aout 2015'!J12+'Septembre 2015'!J14+'Octobre 2015'!J14+'Novembre 2015'!J14+'Decembre 2015'!J14 -> 0 | K14: =SUM(G14:J14) -> 11 | L14: =SUM(F14+K14) -> 12
A15: 6 | B15: ='JANVIER 2015'!B14+'FEVRIER 2015'!B13+'Mars 2015'!B15+'Avril 2015'!B15+'Mai 2015'!B15+'Juin 2015'!B15+'Juillet 2015'!B15+'Aout 2015'!B13+'Septembre 2015'!B15+'Octobre 2015'!B15+'Novembre 2015'!B15+'Decembre 2015'!B15 -> 5 | C15: ='JANVIER 2015'!C14+'FEVRIER 2015'!C13+'Mars 2015'!C15+'Avril 2015'!C15+'Mai 2015'!C15+'Juin 2015'!C15+'Juillet 2015'!C15+'Aout 2015'!C13+'Septembre 2015'!C15+'Octobre 2015'!C15+'Novembre 2015'!C15+'Decembre 2015'!C15 -> 0 | D15: ='JANVIER 2015'!D14+'FEVRIER 2015'!D13+'Mars 2015'!D15+'Avril 2015'!D15+'Mai 2015'!D15+'Juin 2015'!D15+'Juillet 2015'!D15+'Aout 2015'!D13+'Septembre 2015'!D15+'Octobre 2015'!D15+'Novembre 2015'!D15+'Decembre 2015'!D15 -> 1 | E15: ='JANVIER 2015'!E14+'FEVRIER 2015'!E13+'Mars 2015'!E15+'Avril 2015'!E15+'Mai 2015'!E15+'Juin 2015'!E15+'Juillet 2015'!E15+'Aout 2015'!E13+'Septembre 2015'!E15+'Octobre 2015'!E15+'Novembre 2015'!E15+'Decembre 2015'!E15 -> 1 | F15: =SUM(B15:E15) -> 7 | G15: ='JANVIER 2015'!G14+'FEVRIER 2015'!G13+'Mars 2015'!G15+'Avril 2015'!G15+'Mai 2015'!G15+'Juin 2015'!G15+'Juillet 2015'!G15+'Aout 2015'!G13+'Septembre 2015'!G15+'Octobre 2015'!G15+'Novembre 2015'!G15+'Decembre 2015'!G15 -> 12 | H15: ='JANVIER 2015'!H14+'FEVRIER 2015'!H13+'Mars 2015'!H15+'Avril 2015'!H15+'Mai 2015'!H15+'Juin 2015'!H15+'Juillet 2015'!H15+'Aout 2015'!H13+'Septembre 2015'!H15+'Octobre 2015'!H15+'Novembre 2015'!H15+'Decembre 2015'!H15 -> 0 | I15: ='JANVIER 2015'!I14+'FEVRIER 2015'!I13+'Mars 2015'!I15+'Avril 2015'!I15+'Mai 2015'!I15+'Juin 2015'!I15+'Juillet 2015'!I15+'Aout 2015'!I13+'Septembre 2015'!I15+'Octobre 2015'!I15+'Novembre 2015'!I15+'Decembre 2015'!I15 -> 0 | J15: ='JANVIER 2015'!J14+'FEVRIER 2015'!J13+'Mars 2015'!J15+'Avril 2015'!J15+'Mai 2015'!J15+'Juin 2015'!J15+'Juillet 2015'!J15+'Aout 2015'!J13+'Septembre 2015'!J15+'Octobre 2015'!J15+'Novembre 2015'!J15+'Decembre 2015'!J15 -> 0 | K15: =SUM(G15:J15) -> 12 | L15: =SUM(F15+K15) -> 19
A16: 7 | B16: ='JANVIER 2015'!B15+'FEVRIER 2015'!B14+'Mars 2015'!B16+'Avril 2015'!B16+'Mai 2015'!B16+'Juin 2015'!B16+'Juillet 2015'!B16+'Aout 2015'!B14+'Septembre 2015'!B16+'Octobre 2015'!B16+'Novembre 2015'!B16+'Decembre 2015'!B16 -> 6 | C16: ='JANVIER 2015'!C15+'FEVRIER 2015'!C14+'Mars 2015'!C16+'Avril 2015'!C16+'Mai 2015'!C16+'Juin 2015'!C16+'Juillet 2015'!C16+'Aout 2015'!C14+'Septembre 2015'!C16+'Octobre 2015'!C16+'Novembre 2015'!C16+'Decembre 2015'!C16 -> 0 | D16: ='JANVIER 2015'!D15+'FEVRIER 2015'!D14+'Mars 2015'!D16+'Avril 2015'!D16+'Mai 2015'!D16+'Juin 2015'!D16+'Juillet 2015'!D16+'Aout 2015'!D14+'Septembre 2015'!D16+'Octobre 2015'!D16+'Novembre 2015'!D16+'Decembre 2015'!D16 -> 0 | E16: ='JANVIER 2015'!E15+'FEVRIER 2015'!E14+'Mars 2015'!E16+'Avril 2015'!E16+'Mai 2015'!E16+'Juin 2015'!E16+'Juillet 2015'!E16+'Aout 2015'!E14+'Septembre 2015'!E16+'Octobre 2015'!E16+'Novembre 2015'!E16+'Decembre 2015'!E16 -> 0 | F16: =SUM(B16:E16) -> 6 | G16: ='JANVIER 2015'!G15+'FEVRIER 2015'!G14+'Mars 2015'!G16+'Avril 2015'!G16+'Mai 2015'!G16+'Juin 2015'!G16+'Juillet 2015'!G16+'Aout 2015'!G14+'Septembre 2015'!G16+'Octobre 2015'!G16+'Novembre 2015'!G16+'Decembre 2015'!G16 -> 13 | H16: ='JANVIER 2015'!H15+'FEVRIER 2015'!H14+'Mars 2015'!H16+'Avril 2015'!H16+'Mai 2015'!H16+'Juin 2015'!H16+'Juillet 2015'!H16+'Aout 2015'!H14+'Septembre 2015'!H16+'Octobre 2015'!H16+'Novembre 2015'!H16+'Decembre 2015'!H16 -> 1 | I16: ='JANVIER 2015'!I15+'FEVRIER 2015'!I14+'Mars 2015'!I16+'Avril 2015'!I16+'Mai 2015'!I16+'Juin 2015'!I16+'Juillet 2015'!I16+'Aout 2015'!I14+'Septembre 2015'!I16+'Octobre 2015'!I16+'Novembre 2015'!I16+'Decembre 2015'!I16 -> 0 | J16: ='JANVIER 2015'!J15+'FEVRIER 2015'!J14+'Mars 2015'!J16+'Avril 2015'!J16+'Mai 2015'!J16+'Juin 2015'!J16+'Juillet 2015'!J16+'Aout 2015'!J14+'Septembre 2015'!J16+'Octobre 2015'!J16+'Novembre 2015'!J16+'Decembre 2015'!J16 -> 1 | K16: =SUM(G16:J16) -> 15 | L16: =SUM(F16+K16) -> 21
A17: 8 | B17: ='JANVIER 2015'!B16+'FEVRIER 2015'!B15+'Mars 2015'!B17+'Avril 2015'!B17+'Mai 2015'!B17+'Juin 2015'!B17+'Juillet 2015'!B17+'Aout 2015'!B15+'Septembre 2015'!B17+'Octobre 2015'!B17+'Novembre 2015'!B17+'Decembre 2015'!B17 -> 7 | C17: ='JANVIER 2015'!C16+'FEVRIER 2015'!C15+'Mars 2015'!C17+'Avril 2015'!C17+'Mai 2015'!C17+'Juin 2015'!C17+'Juillet 2015'!C17+'Aout 2015'!C15+'Septembre 2015'!C17+'Octobre 2015'!C17+'Novembre 2015'!C17+'Decembre 2015'!C17 -> 0 | D17: ='JANVIER 2015'!D16+'FEVRIER 2015'!D15+'Mars 2015'!D17+'Avril 2015'!D17+'Mai 2015'!D17+'Juin 2015'!D17+'Juillet 2015'!D17+'Aout 2015'!D15+'Septembre 2015'!D17+'Octobre 2015'!D17+'Novembre 2015'!D17+'Decembre 2015'!D17 -> 0 | E17: ='JANVIER 2015'!E16+'FEVRIER 2015'!E15+'Mars 2015'!E17+'Avril 2015'!E17+'Mai 2015'!E17+'Juin 2015'!E17+'Juillet 2015'!E17+'Aout 2015'!E15+'Septembre 2015'!E17+'Octobre 2015'!E17+'Novembre 2015'!E17+'Decembre 2015'!E17 -> 0 | F17: =SUM(B17:E17) -> 7 | G17: ='JANVIER 2015'!G16+'FEVRIER 2015'!G15+'Mars 2015'!G17+'Avril 2015'!G17+'Mai 2015'!G17+'Juin 2015'!G17+'Juillet 2015'!G17+'Aout 2015'!G15+'Septembre 2015'!G17+'Octobre 2015'!G17+'Novembre 2015'!G17+'Decembre 2015'!G17 -> 18 | H17: ='JANVIER 2015'!H16+'FEVRIER 2015'!H15+'Mars 2015'!H17+'Avril 2015'!H17+'Mai 2015'!H17+'Juin 2015'!H17+'Juillet 2015'!H17+'Aout 2015'!H15+'Septembre 2015'!H17+'Octobre 2015'!H17+'Novembre 2015'!H17+'Decembre 2015'!H17 -> 1 | I17: ='JANVIER 2015'!I16+'FEVRIER 2015'!I15+'Mars 2015'!I17+'Avril 2015'!I17+'Mai 2015'!I17+'Juin 2015'!I17+'Juillet 2015'!I17+'Aout 2015'!I15+'Septembre 2015'!I17+'Octobre 2015'!I17+'Novembre 2015'!I17+'Decembre 2015'!I17 -> 0 | J17: ='JANVIER 2015'!J16+'FEVRIER 2015'!J15+'Mars 2015'!J17+'Avril 2015'!J17+'Mai 2015'!J17+'Juin 2015'!J17+'Juillet 2015'!J17+'Aout 2015'!J15+'Septembre 2015'!J17+'Octobre 2015'!J17+'Novembre 2015'!J17+'Decembre 2015'!J17 -> 1 | K17: =SUM(G17:J17) -> 20 | L17: =SUM(F17+K17) -> 27
A18: 9 | B18: ='JANVIER 2015'!B17+'FEVRIER 2015'!B16+'Mars 2015'!B18+'Avril 2015'!B18+'Mai 2015'!B18+'Juin 2015'!B18+'Juillet 2015'!B18+'Aout 2015'!B16+'Septembre 2015'!B18+'Octobre 2015'!B18+'Novembre 2015'!B18+'Decembre 2015'!B18 -> 4 | C18: ='JANVIER 2015'!C17+'FEVRIER 2015'!C16+'Mars 2015'!C18+'Avril 2015'!C18+'Mai 2015'!C18+'Juin 2015'!C18+'Juillet 2015'!C18+'Aout 2015'!C16+'Septembre 2015'!C18+'Octobre 2015'!C18+'Novembre 2015'!C18+'Decembre 2015'!C18 -> 0 | D18: ='JANVIER 2015'!D17+'FEVRIER 2015'!D16+'Mars 2015'!D18+'Avril 2015'!D18+'Mai 2015'!D18+'Juin 2015'!D18+'Juillet 2015'!D18+'Aout 2015'!D16+'Septembre 2015'!D18+'Octobre 2015'!D18+'Novembre 2015'!D18+'Decembre 2015'!D18 -> 2 | E18: ='JANVIER 2015'!E17+'FEVRIER 2015'!E16+'Mars 2015'!E18+'Avril 2015'!E18+'Mai 2015'!E18+'Juin 2015'!E18+'Juillet 2015'!E18+'Aout 2015'!E16+'Septembre 2015'!E18+'Octobre 2015'!E18+'Novembre 2015'!E18+'Decembre 2015'!E18 -> 0 | F18: =SUM(B18:E18) -> 6 | G18: ='JANVIER 2015'!G17+'FEVRIER 2015'!G16+'Mars 2015'!G18+'Avril 2015'!G18+'Mai 2015'!G18+'Juin 2015'!G18+'Juillet 2015'!G18+'Aout 2015'!G16+'Septembre 2015'!G18+'Octobre 2015'!G18+'Novembre 2015'!G18+'Decembre 2015'!G18 -> 6 | H18: ='JANVIER 2015'!H17+'FEVRIER 2015'!H16+'Mars 2015'!H18+'Avril 2015'!H18+'Mai 2015'!H18+'Juin 2015'!H18+'Juillet 2015'!H18+'Aout 2015'!H16+'Septembre 2015'!H18+'Octobre 2015'!H18+'Novembre 2015'!H18+'Decembre 2015'!H18 -> 0 | I18: ='JANVIER 2015'!I17+'FEVRIER 2015'!I16+'Mars 2015'!I18+'Avril 2015'!I18+'Mai 2015'!I18+'Juin 2015'!I18+'Juillet 2015'!I18+'Aout 2015'!I16+'Septembre 2015'!I18+'Octobre 2015'!I18+'Novembre 2015'!I18+'Decembre 2015'!I18 -> 0 | J18: ='JANVIER 2015'!J17+'FEVRIER 2015'!J16+'Mars 2015'!J18+'Avril 2015'!J18+'Mai 2015'!J18+'Juin 2015'!J18+'Juillet 2015'!J18+'Aout 2015'!J16+'Septembre 2015'!J18+'Octobre 2015'!J18+'Novembre 2015'!J18+'Decembre 2015'!J18 -> 0 | K18: =SUM(G18:J18) -> 6 | L18: =SUM(F18+K18) -> 12
